Workbook

Sheet BOOTHWISE
A1: Booth | C1: No of Valid Votes Cast in favor of | K1: Total of Valid Votes | L1: No.Of Rejected votes | M1: NOTA | N1: Total | O1: No.Of Tendered Votes
C3: J.R.LOBO | D3: D.VEDAVYASA KAMATH | E3: S | F3: K.SANTHOSH KAMATH | G3: DHARMENDRA | H3: WINNY PINTO | I3: S | J3: K.S.PAI | P3: total analytics | Q3: TOTAL VOTERS
A7: 1 | C7: 273 | D7: 500 | E7: 1 | F7: 2 | G7: 1 | H7: 0 | I7: 1 | J7: 0 | K7: 778 | L7: 0 | M7: 6 | N7: 784 | O7: 0 | P7: =C7+D7+E7+F7+G7+H7+I7+J7+M7 -> 784
A8: 2 | B8: 2 | C8: 208 | D8: 521 | E8: 2 | F8: 2 | G8: 0 | H8: 0 | I8: 3 | J8: 2 | K8: 738 | L8: 0 | M8: 4 | N8: 742 | O8: 0 | P8: =C8+D8+E8+F8+G8+H8+I8+J8+M8 -> 742
A9: 3 | B9: 3 | C9: 191 | D9: 278 | E9: 2 | F9: 0 | G9: 0 | H9: 1 | I9: 1 | J9: 0 | K9: 473 | L9: 0 | M9: 5 | N9: 478 | O9: 0 | P9: =C9+D9+E9+F9+G9+H9+I9+J9+M9 -> 478
A10: 4 | C10: 205 | D10: 736 | E10: 0 | F10: 9 | G10: 1 | H10: 0 | I10: 3 | J10: 2 | K10: 956 | L10: 0 | M10: 13 | N10: 969 | O10: 0 | P10: =C10+D10+E10+F10+G10+H10+I10+J10+M10 -> 969
A11: 5 | C11: 180 | D11: 598 | E11: 2 | F11: 1 | G11: 1 | H11: 2 | I11: 3 | J11: 1 | K11: 788 | L11: 0 | M11: 8 | N11: 796 | O11: 0 | P11: =C11+D11+E11+F11+G11+H11+I11+J11+M11 -> 796
A12: 6 | C12: 388 | D12: 497 | E12: 5 | F12: 1 | G12: 0 | H12: 0 | I12: 1 | J12: 1 | K12: 893 | L12: 0 | M12: 10 | N12: 903 | O12: 0 | P12: =C12+D12+E12+F12+G12+H12+I12+J12+M12 -> 903
A13: 7 | C13: 130 | D13: 375 | E13: 2 | F13: 1 | G13: 0 | H13: 0 | I13: 0 | J13: 0 | K13: 508 | L13: 0 | M13: 2 | N13: 510 | O13: 0 | P13: =C13+D13+E13+F13+G13+H13+I13+J13+M13 -> 510
A14: 8 | C14: 161 | D14: 366 | E14: 1 | F14: 2 | G14: 0 | H14: 0 | I14: 0 | J14: 0 | K14: 530 | L14: 0 | M14: 8 | N14: 538 | O14: 0 | P14: =C14+D14+E14+F14+G14+H14+I14+J14+M14 -> 538
A15: 9 | C15: 248 | D15: 392 | E15: 10 | F15: 4 | G15: 0 | H15: 1 | I15: 1 | J15: 0 | K15: 656 | L15: 0 | M15: 8 | N15: 664 | O15: 0 | P15: =C15+D15+E15+F15+G15+H15+I15+J15+M15 -> 664
A16: 10 | C16: 128 | D16: 340 | E16: 4 | F16: 1 | G16: 0 | H16: 1 | I16: 1 | J16: 0 | K16: 475 | L16: 0 | M16: 4 | N16: 479 | O16: 0 | P16: =C16+D16+E16+F16+G16+H16+I16+J16+M16 -> 479
A17: 11 | C17: 317 | D17: 567 | E17: 5 | F17: 2 | G17: 1 | H17: 0 | I17: 0 | J17: 0 | K17: 892 | L17: 0 | M17: 5 | N17: 897 | O17: 0 | P17: =C17+D17+E17+F17+G17+H17+I17+J17+M17 -> 897
A18: 12 | C18: 167 | D18: 343 | E18: 1 | F18: 5 | G18: 0 | H18: 0 | I18: 1 | J18: 1 | K18: 518 | L18: 0 | M18: 4 | N18: 522 | O18: 0 | P18: =C18+D18+E18+F18+G18+H18+I18+J18+M18 -> 522
A19: 13 | C19: 222 | D19: 391 | E19: 2 | F19: 1 | G19: 1 | H19: 2 | I19: 0 | J19: 0 | K19: 619 | L19: 0 | M19: 5 | N19: 624 | O19: 0 | P19: =C19+D19+E19+F19+G19+H19+I19+J19+M19 -> 624
A20: 14 | C20: 98 | D20: 273 | E20: 3 | F20: 5 | G20: 0 | H20: 0 | I20: 0 | J20: 0 | K20: 379 | L20: 0 | M20: 2 | N20: 381 | O20: 0 | P20: =C20+D20+E20+F20+G20+H20+I20+J20+M20 -> 381
A21: 15 | C21: 119 | D21: 168 | E21: 1 | F21: 2 | G21: 0 | H21: 2 | I21: 1 | J21: 0 | K21: 293 | L21: 0 | M21: 1 | N21: 294 | O21: 0 | P21: =C21+D21+E21+F21+G21+H21+I21+J21+M21 -> 294
... A250: 244 | C250: 424 | D250: 73 | E250: 0 | F250: 0 | G250: 0 | H250: 0 | I250: 1 | J250: 0 | K250: 498 | L250: 0 | M250: 0 | N250: 498 | O250: 0 | P250: =C250+D250+E250+F250+G250+H250+I250+J250+M250 -> 498
K251: =SUM(K7:K250) -> 162394 | N251: =SUM(N7:N250) -> 159414 | P251: =SUM(P7:P250) -> 159420

Sheet WARD-BOOTH
A1: WARD NAME | B1: Booth | C1: TOTAL VOTERS | D1: No of Valid Votes Cast in favor of | L1: Total of Valid Votes | M1: No.Of Rejected votes | N1: NOTA | O1: Total | P1: TOTAL POLLING % | Q1: BJP% | R1: CONGRESS % | S1: JDS % | T1: AAP% | U1: TOTAL INDEPENDENT % | V1: NOTA% | W1: TEMPTOTAL | X1: APP ENTRY TALLY
D3: J.R.LOBO | E3: D.VEDAVYASA KAMATH | F3: S | G3: K.SANTHOSH KAMATH | H3: DHARMENDRA | I3: WINNY PINTO | J3: S | K3: K.S.PAI
Y4: DIFFERENCE
A7: ALAPE NORTH | B7: 44 | C7: 1158 | D7: 182 | E7: 600 | F7: 3 | G7: 1 | H7: 1 | I7: 0 | J7: 5 | K7: 2 | L7: 794 | M7: 0 | N7: 5 | O7: =D7+E7+F7+G7+H7+I7+J7+K7+N7 -> 799 | P7: =(O7/C7)*100 -> 68.998273 | Q7: =(E7/O7)*100 -> 75.093867 | R7: =(D7/O7)*100 -> 22.778473 | S7: =(F7/O7)*100 -> 0.37546934 | T7: =(G7/O7)*100 -> 0.12515645 | U7: =((H7+I7+J7+K7)/O7)*100 -> 1.0012516 | V7: =(N7/O7)*100 -> 0.62578223 | W7: =Q7+R7+S7+T7+U7+V7 -> 100 | X7: 66.75 | Y7: =P7-X7 -> 2.2482729
B8: 189 | C8: 830 | D8: 250 | E8: 282 | F8: 0 | G8: 1 | H8: 0 | I8: 0 | J8: 1 | K8: 0 | L8: 534 | M8: 0 | N8: 2 | O8: =D8+E8+F8+G8+H8+I8+J8+K8+N8 -> 536 | P8: =(O8/C8)*100 -> 64.578313 | Q8: =(E8/O8)*100 -> 52.61194 | R8: =(D8/O8)*100 -> 46.641791 | S8: =(F8/O8)*100 -> 0 | T8: =(G8/O8)*100 -> 0.18656716 | U8: =((H8+I8+J8+K8)/O8)*100 -> 0.18656716 | V8: =(N8/O8)*100 -> 0.37313433 | W8: =Q8+R8+S8+T8+U8+V8 -> 100 | X8: 62.77 | Y8: =P8-X8 -> 1.8083133
B9: 191 | C9: 1339 | D9: 418 | E9: 376 | F9: 6 | G9: 4 | H9: 1 | I9: 2 | J9: 1 | K9: 1 | L9: 809 | M9: 0 | N9: 6 | O9: 815 | P9: =(O9/C9)*100 -> 60.866318 | Q9: =(E9/O9)*100 -> 46.134969 | R9: =(D9/O9)*100 -> 51.288344 | S9: =(F9/O9)*100 -> 0.73619632 | T9: =(G9/O9)*100 -> 0.49079755 | U9: =((H9+I9+J9+K9)/O9)*100 -> 0.61349693 | V9: =(N9/O9)*100 -> 0.73619632 | W9: =Q9+R9+S9+T9+U9+V9 -> 100 | X9: 54 | Y9: =P9-X9 -> 6.8663181
B10: 190 | C10: 774 | D10: 241 | E10: 251 | F10: 1 | G10: 0 | H10: 1 | I10: 0 | J10: 0 | K10: 0 | L10: 494 | M10: 0 | N10: 2 | O10: 496 | P10: =(O10/C10)*100 -> 64.082687 | Q10: =(E10/O10)*100 -> 50.604839 | R10: =(D10/O10)*100 -> 48.58871 | S10: =(F10/O10)*100 -> 0.2016129 | T10: =(G10/O10)*100 -> 0 | U10: =((H10+I10+J10+K10)/O10)*100 -> 0.2016129 | V10: =(N10/O10)*100 -> 0.40322581 | W10: =Q10+R10+S10+T10+U10+V10 -> 100 | X10: 63.7 | Y10: =P10-X10 -> 0.38268734
B11: 192 | C11: 1034 | D11: 330 | E11: 337 | F11: 2 | G11: 1 | H11: 1 | I11: 0 | J11: 2 | K11: 0 | L11: 673 | M11: 0 | N11: 5 | O11: 678 | P11: =(O11/C11)*100 -> 65.5706 | Q11: =(E11/O11)*100 -> 49.705015 | R11: =(D11/O11)*100 -> 48.672566 | S11: =(F11/O11)*100 -> 0.29498525 | T11: =(G11/O11)*100 -> 0.14749263 | U11: =((H11+I11+J11+K11)/O11)*100 -> 0.44247788 | V11: =(N11/O11)*100 -> 0.73746313 | W11: =Q11+R11+S11+T11+U11+V11 -> 100 | X11: 51.74 | Y11: =P11-X11 -> 13.8306
B12: 197 | C12: 1294 | D12: 360 | E12: 543 | F12: 1 | G12: 1 | H12: 0 | I12: 0 | J12: 2 | K12: 1 | L12: 908 | M12: 0 | N12: 9 | O12: 917 | P12: =(O12/C12)*100 -> 70.865533 | Q12: =(E12/O12)*100 -> 59.214831 | R12: =(D12/O12)*100 -> 39.258451 | S12: =(F12/O12)*100 -> 0.10905125 | T12: =(G12/O12)*100 -> 0.10905125 | U12: =((H12+I12+J12+K12)/O12)*100 -> 0.32715376 | V12: =(N12/O12)*100 -> 0.98146129 | W12: =Q12+R12+S12+T12+U12+V12 -> 100 | X12: 68.62 | Y12: =P12-X12 -> 2.2455332
B13: 45 | C13: 704 | D13: 171 | E13: 350 | F13: 1 | G13: 0 | H13: 0 | I13: 0 | J13: 0 | K13: 2 | L13: 524 | M13: 0 | N13: 2 | O13: =D13+E13+F13+G13+H13+I13+J13+K13+N13 -> 526 | P13: =(O13/C13)*100 -> 74.715909 | Q13: =(E13/O13)*100 -> 66.539924 | R13: =(D13/O13)*100 -> 32.509506 | S13: =(F13/O13)*100 -> 0.19011407 | T13: =(G13/O13)*100 -> 0 | U13: =((H13+I13+J13+K13)/O13)*100 -> 0.38022814 | V13: =(N13/O13)*100 -> 0.38022814 | W13: =Q13+R13+S13+T13+U13+V13 -> 100 | X13: 76.56 | Y13: =P13-X13 -> -1.8440909
A14: ALAPE SOUTH | B14: 188 | C14: 1077 | D14: 250 | E14: 476 | F14: 2 | G14: 0 | H14: 0 | I14: 0 | J14: 0 | K14: 1 | L14: 729 | M14: 0 | N14: 4 | O14: =D14+E14+F14+G14+H14+I14+J14+K14+N14 -> 733 | P14: =(O14/C14)*100 -> 68.059424 | Q14: =(E14/O14)*100 -> 64.938608 | R14: =(D14/O14)*100 -> 34.106412 | S14: =(F14/O14)*100 -> 0.2728513 | T14: =(G14/O14)*100 -> 0 | U14: =((H14+I14+J14+K14)/O14)*100 -> 0.13642565 | V14: =(N14/O14)*100 -> 0.54570259 | W14: =Q14+R14+S14+T14+U14+V14 -> 100 | X14: 66.11 | Y14: =P14-X14 -> 1.9494243
B15: 187 | C15: 1008 | D15: 135 | E15: 583 | F15: 3 | G15: 7 | H15: 0 | I15: 0 | J15: 0 | K15: 1 | L15: 729 | M15: 0 | N15: 4 | O15: =D15+E15+F15+G15+H15+I15+J15+K15+N15 -> 733 | P15: =(O15/C15)*100 -> 72.718254 | Q15: =(E15/O15)*100 -> 79.536153 | R15: =(D15/O15)*100 -> 18.417462 | S15: =(F15/O15)*100 -> 0.40927694 | T15: =(G15/O15)*100 -> 0.95497954 | U15: =((H15+I15+J15+K15)/O15)*100 -> 0.13642565 | V15: =(N15/O15)*100 -> 0.54570259 | W15: =Q15+R15+S15+T15+U15+V15 -> 100 | X15: 69.84 | Y15: =P15-X15 -> 2.878254
B16: 186 | C16: 823 | D16: 162 | E16: 450 | F16: 0 | G16: 4 | H16: 0 | I16: 0 | J16: 2 | K16: 3 | L16: 622 | M16: 0 | N16: 7 | O16: =D16+E16+F16+G16+H16+I16+J16+K16+N16 -> 628 | P16: =(O16/C16)*100 -> 76.306197 | Q16: =(E16/O16)*100 -> 71.656051 | R16: =(D16/O16)*100 -> 25.796178 | S16: =(F16/O16)*100 -> 0 | T16: =(G16/O16)*100 -> 0.63694268 | U16: =((H16+I16+J16+K16)/O16)*100 -> 0.79617834 | V16: =(N16/O16)*100 -> 1.1146497 | W16: =Q16+R16+S16+T16+U16+V16 -> 100 | X16: 73.15 | Y16: =P16-X16 -> 3.1561968
B17: 185 | C17: 523 | D17: 148 | E17: 174 | F17: 1 | G17: 1 | H17: 0 | I17: 0 | J17: 0 | K17: 0 | L17: 324 | M17: 0 | N17: 5 | O17: =D17+E17+F17+G17+H17+I17+J17+K17+N17 -> 329 | P17: =(O17/C17)*100 -> 62.90631 | Q17: =(E17/O17)*100 -> 52.887538 | R17: =(D17/O17)*100 -> 44.984802 | S17: =(F17/O17)*100 -> 0.30395137 | T17: =(G17/O17)*100 -> 0.30395137 | U17: =((H17+I17+J17+K17)/O17)*100 -> 0 | V17: =(N17/O17)*100 -> 1.5197568 | W17: =Q17+R17+S17+T17+U17+V17 -> 100 | X17: 58.13 | Y17: =P17-X17 -> 4.7763098
B18: 184 | C18: 841 | D18: 128 | E18: 402 | F18: 2 | G18: 7 | H18: 1 | I18: 0 | J18: 0 | K18: 3 | L18: 543 | M18: 0 | N18: 2 | O18: =D18+E18+F18+G18+H18+I18+J18+K18+N18 -> 545 | P18: =(O18/C18)*100 -> 64.803805 | Q18: =(E18/O18)*100 -> 73.761468 | R18: =(D18/O18)*100 -> 23.486239 | S18: =(F18/O18)*100 -> 0.36697248 | T18: =(G18/O18)*100 -> 1.2844037 | U18: =((H18+I18+J18+K18)/O18)*100 -> 0.73394495 | V18: =(N18/O18)*100 -> 0.36697248 | W18: =Q18+R18+S18+T18+U18+V18 -> 100 | X18: 62.9 | Y18: =P18-X18 -> 1.903805
B19: 209 | C19: 777 | D19: 218 | E19: 361 | F19: 1 | G19: 4 | H19: 0 | I19: 0 | J19: 0 | K19: 0 | L19: 584 | M19: 0 | N19: 2 | O19: =D19+E19+F19+G19+H19+I19+J19+K19+N19 -> 586 | P19: =(O19/C19)*100 -> 75.418275 | Q19: =(E19/O19)*100 -> 61.604096 | R19: =(D19/O19)*100 -> 37.201365 | S19: =(F19/O19)*100 -> 0.17064846 | T19: =(G19/O19)*100 -> 0.68259386 | U19: =((H19+I19+J19+K19)/O19)*100 -> 0 | V19: =(N19/O19)*100 -> 0.34129693 | W19: =Q19+R19+S19+T19+U19+V19 -> 100 | X19: 66.28 | Y19: =P19-X19 -> 9.1382754
B20: 210 | C20: 663 | D20: 153 | E20: 300 | F20: 5 | G20: 2 | H20: 0 | I20: 0 | J20: 0 | K20: 1 | L20: 461 | M20: 0 | N20: 1 | O20: =D20+E20+F20+G20+H20+I20+J20+K20+N20 -> 462 | P20: =(O20/C20)*100 -> 69.683258 | Q20: =(E20/O20)*100 -> 64.935065 | R20: =(D20/O20)*100 -> 33.116883 | S20: =(F20/O20)*100 -> 1.0822511 | T20: =(G20/O20)*100 -> 0.43290043 | U20: =((H20+I20+J20+K20)/O20)*100 -> 0.21645022 | V20: =(N20/O20)*100 -> 0.21645022 | W20: =Q20+R20+S20+T20+U20+V20 -> 100 | X20: 68.33 | Y20: =P20-X20 -> 1.3532579
A21: ATHAVARA | B21: 152 | C21: 694 | D21: 182 | E21: 268 | F21: 0 | G21: 0 | H21: 0 | I21: 1 | J21: 0 | K21: 0 | L21: 451 | M21: 0 | N21: 2 | O21: =D21+E21+F21+G21+H21+I21+J21+K21+N21 -> 453 | P21: =(O21/C21)*100 -> 65.273775 | Q21: =(E21/O21)*100 -> 59.161148 | R21: =(D21/O21)*100 -> 40.1766 | S21: =(F21/O21)*100 -> 0 | T21: =(G21/O21)*100 -> 0 | U21: =((H21+I21+J21+K21)/O21)*100 -> 0.22075055 | V21: =(N21/O21)*100 -> 0.4415011 | W21: =Q21+R21+S21+T21+U21+V21 -> 100 | X21: 61.38 | Y21: =P21-X21 -> 3.8937752
B22: 151 | C22: 967 | D22: 149 | E22: 438 | F22: 2 | G22: 2 | H22: 0 | I22: 1 | J22: 0 | K22: 0 | L22: 592 | M22: 0 | N22: 3 | O22: =D22+E22+F22+G22+H22+I22+J22+K22+N22 -> 595 | P22: =(O22/C22)*100 -> 61.530507 | Q22: =(E22/O22)*100 -> 73.613445 | R22: =(D22/O22)*100 -> 25.042017 | S22: =(F22/O22)*100 -> 0.33613445 | T22: =(G22/O22)*100 -> 0.33613445 | U22: =((H22+I22+J22+K22)/O22)*100 -> 0.16806723 | V22: =(N22/O22)*100 -> 0.50420168 | W22: =Q22+R22+S22+T22+U22+V22 -> 100 | X22: 59.05 | Y22: =P22-X22 -> 2.4805067
B23: 242 | C23: 1008 | D23: 481 | E23: 174 | F23: 0 | G23: 0 | H23: 0 | I23: 1 | J23: 1 | K23: 0 | L23: 657 | M23: 0 | N23: 1 | O23: =D23+E23+F23+G23+H23+I23+J23+K23+N23 -> 658 | P23: =(O23/C23)*100 -> 65.277778 | Q23: =(E23/O23)*100 -> 26.443769 | R23: =(D23/O23)*100 -> 73.100304 | S23: =(F23/O23)*100 -> 0 | T23: =(G23/O23)*100 -> 0 | U23: =((H23+I23+J23+K23)/O23)*100 -> 0.30395137 | V23: =(N23/O23)*100 -> 0.15197568 | W23: =Q23+R23+S23+T23+U23+V23 -> 100 | X23: 64.48 | Y23: =P23-X23 -> 0.79777778
B24: 243 | C24: 964 | D24: 254 | E24: 397 | F24: 3 | G24: 5 | H24: 1 | I24: 0 | J24: 0 | K24: 1 | L24: 661 | M24: 0 | N24: 5 | O24: =D24+E24+F24+G24+H24+I24+J24+K24+N24 -> 666 | P24: =(O24/C24)*100 -> 69.087137 | Q24: =(E24/O24)*100 -> 59.60961 | R24: =(D24/O24)*100 -> 38.138138 | S24: =(F24/O24)*100 -> 0.45045045 | T24: =(G24/O24)*100 -> 0.75075075 | U24: =((H24+I24+J24+K24)/O24)*100 -> 0.3003003 | V24: =(N24/O24)*100 -> 0.75075075 | W24: =Q24+R24+S24+T24+U24+V24 -> 100 | X24: 66.7 | Y24: =P24-X24 -> 2.3871369
B25: 221 | C25: 1018 | D25: 320 | E25: 275 | F25: 4 | G25: 1 | H25: 0 | I25: 0 | J25: 1 | K25: 0 | L25: 601 | M25: 0 | N25: 2 | O25: =D25+E25+F25+G25+H25+I25+J25+K25+N25 -> 603 | P25: =(O25/C25)*100 -> 59.233792 | Q25: =(E25/O25)*100 -> 45.605307 | R25: =(D25/O25)*100 -> 53.067993 | S25: =(F25/O25)*100 -> 0.66334992 | T25: =(G25/O25)*100 -> 0.16583748 | U25: =((H25+I25+J25+K25)/O25)*100 -> 0.16583748 | V25: =(N25/O25)*100 -> 0.33167496 | W25: =Q25+R25+S25+T25+U25+V25 -> 100 | X25: 58.45 | Y25: =P25-X25 -> 0.78379175
B26: 222 | C26: 1092 | D26: 332 | E26: 330 | F26: 2 | G26: 5 | H26: 0 | I26: 1 | J26: 2 | K26: 0 | L26: 672 | M26: 0 | N26: 3 | O26: =D26+E26+F26+G26+H26+I26+J26+K26+N26 -> 675 | P26: =(O26/C26)*100 -> 61.813187 | Q26: =(E26/O26)*100 -> 48.888889 | R26: =(D26/O26)*100 -> 49.185185 | S26: =(F26/O26)*100 -> 0.2962963 | T26: =(G26/O26)*100 -> 0.74074074 | U26: =((H26+I26+J26+K26)/O26)*100 -> 0.44444444 | V26: =(N26/O26)*100 -> 0.44444444 | W26: =Q26+R26+S26+T26+U26+V26 -> 100 | X26: 61.17 | Y26: =P26-X26 -> 0.64318681
B27: 153 | C27: 883 | D27: 189 | E27: 397 | F27: 1 | G27: 3 | H27: 0 | I27: 0 | J27: 0 | K27: 1 | L27: 591 | M27: 0 | N27: 4 | O27: =D27+E27+F27+G27+H27+I27+J27+K27+N27 -> 595 | P27: =(O27/C27)*100 -> 67.383918 | Q27: =(E27/O27)*100 -> 66.722689 | R27: =(D27/O27)*100 -> 31.764706 | S27: =(F27/O27)*100 -> 0.16806723 | T27: =(G27/O27)*100 -> 0.50420168 | U27: =((H27+I27+J27+K27)/O27)*100 -> 0.16806723 | V27: =(N27/O27)*100 -> 0.67226891 | W27: =Q27+R27+S27+T27+U27+V27 -> 100 | X27: 64.89 | Y27: =P27-X27 -> 2.4939185
A28: BAJAL | B28: 202 | C28: 1128 | D28: 574 | E28: 251 | F28: 6 | G28: 2 | H28: 1 | I28: 1 | J28: 1 | K28: 1 | L28: 837 | M28: 0 | N28: 1 | O28: =D28+E28+F28+G28+H28+I28+J28+K28+N28 -> 838 | P28: =(O28/C28)*100 -> 74.29078 | Q28: =(E28/O28)*100 -> 29.952267 | R28: =(D28/O28)*100 -> 68.49642 | S28: =(F28/O28)*100 -> 0.71599045 | T28: =(G28/O28)*100 -> 0.23866348 | U28: =((H28+I28+J28+K28)/O28)*100 -> 0.47732697 | V28: =(N28/O28)*100 -> 0.11933174 | W28: =Q28+R28+S28+T28+U28+V28 -> 100 | X28: 65.51 | Y28: =P28-X28 -> 8.7807801
B29: 201 | C29: 1223 | D29: 717 | E29: 66 | F29: 6 | G29: 0 | H29: 0 | I29: 0 | J29: 1 | K29: 1 | L29: 791 | M29: 0 | N29: 7 | O29: =D29+E29+F29+G29+H29+I29+J29+K29+N29 -> 798 | P29: =(O29/C29)*100 -> 65.249387 | Q29: =(E29/O29)*100 -> 8.2706767 | R29: =(D29/O29)*100 -> 89.849624 | S29: =(F29/O29)*100 -> 0.7518797 | T29: =(G29/O29)*100 -> 0 | U29: =((H29+I29+J29+K29)/O29)*100 -> 0.25062657 | V29: =(N29/O29)*100 -> 0.87719298 | W29: =Q29+R29+S29+T29+U29+V29 -> 100 | X29: 30.25 | Y29: =P29-X29 -> 34.999387
B30: 203 | C30: 1423 | D30: 740 | E30: 260 | F30: 38 | G30: 1 | H30: 0 | I30: 2 | J30: 0 | K30: 1 | L30: 1042 | M30: 0 | N30: 1 | O30: =D30+E30+F30+G30+H30+I30+J30+K30+N30 -> 1043 | P30: =(O30/C30)*100 -> 73.295854 | Q30: =(E30/O30)*100 -> 24.928092 | R30: =(D30/O30)*100 -> 70.949185 | S30: =(F30/O30)*100 -> 3.6433365 | T30: =(G30/O30)*100 -> 0.095877277 | U30: =((H30+I30+J30+K30)/O30)*100 -> 0.28763183 | V30: =(N30/O30)*100 -> 0.095877277 | W30: =Q30+R30+S30+T30+U30+V30 -> 100 | X30: 68.66 | Y30: =P30-X30 -> 4.6358538
B31: 204 | C31: 933 | D31: 141 | E31: 527 | F31: 1 | G31: 0 | H31: 0 | I31: 1 | J31: 0 | K31: 3 | L31: 673 | M31: 0 | N31: 7 | O31: =D31+E31+F31+G31+H31+I31+J31+K31+N31 -> 680 | P31: =(O31/C31)*100 -> 72.883173 | Q31: =(E31/O31)*100 -> 77.5 | R31: =(D31/O31)*100 -> 20.735294 | S31: =(F31/O31)*100 -> 0.14705882 | T31: =(G31/O31)*100 -> 0 | U31: =((H31+I31+J31+K31)/O31)*100 -> 0.58823529 | V31: =(N31/O31)*100 -> 1.0294118 | W31: =Q31+R31+S31+T31+U31+V31 -> 100 | X31: 23.04 | Y31: =P31-X31 -> 49.843173
B32: 206 | C32: 721 | D32: 254 | E32: 215 | F32: 26 | G32: 0 | H32: 0 | I32: 0 | J32: 0 | K32: 1 | L32: 496 | M32: 0 | N32: 2 | O32: =D32+E32+F32+G32+H32+I32+J32+K32+N32 -> 498 | P32: =(O32/C32)*100 -> 69.070735 | Q32: =(E32/O32)*100 -> 43.172691 | R32: =(D32/O32)*100 -> 51.004016 | S32: =(F32/O32)*100 -> 5.2208835 | T32: =(G32/O32)*100 -> 0 | U32: =((H32+I32+J32+K32)/O32)*100 -> 0.20080321 | V32: =(N32/O32)*100 -> 0.40160643 | W32: =Q32+R32+S32+T32+U32+V32 -> 100 | X32: 58.95 | Y32: =P32-X32 -> 10.120735
B33: 205 | C33: 1015 | D33: 320 | E33: 350 | F33: 13 | G33: 0 | H33: 0 | I33: 1 | J33: 4 | K33: 1 | L33: 689 | M33: 0 | N33: 3 | O33: =D33+E33+F33+G33+H33+I33+J33+K33+N33 -> 692 | P33: =(O33/C33)*100 -> 68.17734 | Q33: =(E33/O33)*100 -> 50.578035 | R33: =(D33/O33)*100 -> 46.242775 | S33: =(F33/O33)*100 -> 1.8786127 | T33: =(G33/O33)*100 -> 0 | U33: =((H33+I33+J33+K33)/O33)*100 -> 0.86705202 | V33: =(N33/O33)*100 -> 0.43352601 | W33: =Q33+R33+S33+T33+U33+V33 -> 100 | X33: 63.05 | Y33: =P33-X33 -> 5.1273399
B34: 207 | C34: 1230 | D34: 275 | E34: 556 | F34: 3 | G34: 0 | H34: 0 | I34: 0 | J34: 0 | K34: 1 | L34: 835 | M34: 0 | N34: 7 | O34: =D34+E34+F34+G34+H34+I34+J34+K34+N34 -> 842 | P34: =(O34/C34)*100 -> 68.455285 | Q34: =(E34/O34)*100 -> 66.033254 | R34: =(D34/O34)*100 -> 32.660333 | S34: =(F34/O34)*100 -> 0.35629454 | T34: =(G34/O34)*100 -> 0 | U34: =((H34+I34+J34+K34)/O34)*100 -> 0.11876485 | V34: =(N34/O34)*100 -> 0.83135392 | W34: =Q34+R34+S34+T34+U34+V34 -> 100 | X34: 63.01 | Y34: =P34-X34 -> 5.4452846
B35: 208 | C35: 500 | D35: 141 | E35: 181 | F35: 1 | G35: 1 | H35: 0 | I35: 0 | J35: 0 | K35: 0 | L35: 324 | M35: 0 | N35: 0 | O35: =D35+E35+F35+G35+H35+I35+J35+K35+N35 -> 324 | P35: =(O35/C35)*100 -> 64.8 | Q35: =(E35/O35)*100 -> 55.864198 | R35: =(D35/O35)*100 -> 43.518519 | S35: =(F35/O35)*100 -> 0.30864198 | T35: =(G35/O35)*100 -> 0.30864198 | U35: =((H35+I35+J35+K35)/O35)*100 -> 0 | V35: =(N35/O35)*100 -> 0 | W35: =Q35+R35+S35+T35+U35+V35 -> 100 | X35: 63.4 | Y35: =P35-X35 -> 1.4
A36: BEJAI | B36: 15 | C36: 489 | D36: 119 | E36: 168 | F36: 1 | G36: 2 | H36: 0 | I36: 2 | J36: 1 | K36: 0 | L36: 293 | M36: 0 | N36: 1 | O36: =D36+E36+F36+G36+H36+I36+J36+K36+N36 -> 294 | P36: =(O36/C36)*100 -> 60.122699 | Q36: =(E36/O36)*100 -> 57.142857 | R36: =(D36/O36)*100 -> 40.47619 | S36: =(F36/O36)*100 -> 0.34013605 | T36: =(G36/O36)*100 -> 0.68027211 | U36: =((H36+I36+J36+K36)/O36)*100 -> 1.0204082 | V36: =(N36/O36)*100 -> 0.34013605 | W36: =Q36+R36+S36+T36+U36+V36 -> 100 | X36: 52.56 | Y36: =P36-X36 -> 7.5626994
B37: 16 | C37: 1042 | D37: 192 | E37: 439 | F37: 2 | G37: 3 | H37: 1 | I37: 0 | J37: 0 | K37: 0 | L37: 637 | M37: 0 | N37: 9 | O37: =D37+E37+F37+G37+H37+I37+J37+K37+N37 -> 646 | P37: =(O37/C37)*100 -> 61.996161 | Q37: =(E37/O37)*100 -> 67.956656 | R37: =(D37/O37)*100 -> 29.721362 | S37: =(F37/O37)*100 -> 0.30959752 | T37: =(G37/O37)*100 -> 0.46439628 | U37: =((H37+I37+J37+K37)/O37)*100 -> 0.15479876 | V37: =(N37/O37)*100 -> 1.3931889 | W37: =Q37+R37+S37+T37+U37+V37 -> 100 | X37: 57.97 | Y37: =P37-X37 -> 4.0261612
B38: 18 | C38: 1159 | D38: 293 | E38: 392 | F38: 1 | G38: 2 | H38: 1 | I38: 2 | J38: 0 | K38: 0 | L38: 691 | M38: 0 | N38: 5 | O38: =D38+E38+F38+G38+H38+I38+J38+K38+N38 -> 696 | P38: =(O38/C38)*100 -> 60.051769 | Q38: =(E38/O38)*100 -> 56.321839 | R38: =(D38/O38)*100 -> 42.097701 | S38: =(F38/O38)*100 -> 0.14367816 | T38: =(G38/O38)*100 -> 0.28735632 | U38: =((H38+I38+J38+K38)/O38)*100 -> 0.43103448 | V38: =(N38/O38)*100 -> 0.7183908 | W38: =Q38+R38+S38+T38+U38+V38 -> 100 | X38: 56.34 | Y38: =P38-X38 -> 3.7117688
B39: 19 | C39: 1142 | D39: 269 | E39: 472 | F39: 1 | G39: 2 | H39: 0 | I39: 0 | J39: 2 | K39: 0 | L39: 746 | M39: 0 | N39: 11 | O39: =D39+E39+F39+G39+H39+I39+J39+K39+N39 -> 757 | P39: =(O39/C39)*100 -> 66.287215 | Q39: =(E39/O39)*100 -> 62.351387 | R39: =(D39/O39)*100 -> 35.535007 | S39: =(F39/O39)*100 -> 0.1321004 | T39: =(G39/O39)*100 -> 0.26420079 | U39: =((H39+I39+J39+K39)/O39)*100 -> 0.26420079 | V39: =(N39/O39)*100 -> 1.4531044 | W39: =Q39+R39+S39+T39+U39+V39 -> 100 | X39: 58.49 | Y39: =P39-X39 -> 7.7972154
B40: 23 | C40: 1102 | D40: 270 | E40: 458 | F40: 0 | G40: 5 | H40: 0 | I40: 0 | J40: 0 | K40: 0 | L40: 733 | M40: 0 | N40: 7 | O40: =D40+E40+F40+G40+H40+I40+J40+K40+N40 -> 740 | P40: =(O40/C40)*100 -> 67.150635 | Q40: =(E40/O40)*100 -> 61.891892 | R40: =(D40/O40)*100 -> 36.486486 | S40: =(F40/O40)*100 -> 0 | T40: =(G40/O40)*100 -> 0.67567568 | U40: =((H40+I40+J40+K40)/O40)*100 -> 0 | V40: =(N40/O40)*100 -> 0.94594595 | W40: =Q40+R40+S40+T40+U40+V40 -> 100 | X40: 65.52 | Y40: =P40-X40 -> 1.6306352
B41: 21 | C41: 896 | D41: 222 | E41: 284 | F41: 4 | G41: 6 | H41: 0 | I41: 0 | J41: 1 | K41: 0 | L41: 517 | M41: 0 | N41: 6 | O41: =D41+E41+F41+G41+H41+I41+J41+K41+N41 -> 523 | P41: =(O41/C41)*100 -> 58.370536 | Q41: =(E41/O41)*100 -> 54.302103 | R41: =(D41/O41)*100 -> 42.447419 | S41: =(F41/O41)*100 -> 0.76481836 | T41: =(G41/O41)*100 -> 1.1472275 | U41: =((H41+I41+J41+K41)/O41)*100 -> 0.19120459 | V41: =(N41/O41)*100 -> 1.1472275 | W41: =Q41+R41+S41+T41+U41+V41 -> 100 | X41: 58.26 | Y41: =P41-X41 -> 0.11053571
B42: 20 | C42: 1386 | D42: 325 | E42: 439 | F42: 5 | G42: 1 | H42: 0 | I42: 0 | J42: 3 | K42: 1 | L42: 774 | M42: 0 | N42: 8 | O42: =D42+E42+F42+G42+H42+I42+J42+K42+N42 -> 782 | P42: =(O42/C42)*100 -> 56.421356 | Q42: =(E42/O42)*100 -> 56.138107 | R42: =(D42/O42)*100 -> 41.560102 | S42: =(F42/O42)*100 -> 0.63938619 | T42: =(G42/O42)*100 -> 0.12787724 | U42: =((H42+I42+J42+K42)/O42)*100 -> 0.51150895 | V42: =(N42/O42)*100 -> 1.0230179 | W42: =Q42+R42+S42+T42+U42+V42 -> 100 | X42: 55.34 | Y42: =P42-X42 -> 1.0813564
A43: BENDOOR | B43: 162 | C43: 1088 | D43: 431 | E43: 118 | F43: 7 | G43: 1 | H43: 0 | I43: 0 | J43: 0 | K43: 0 | L43: 557 | M43: 0 | N43: 4 | O43: =D43+E43+F43+G43+H43+I43+J43+K43+N43 -> 561 | P43: =(O43/C43)*100 -> 51.5625 | Q43: =(E43/O43)*100 -> 21.033868 | R43: =(D43/O43)*100 -> 76.827094 | S43: =(F43/O43)*100 -> 1.2477718 | T43: =(G43/O43)*100 -> 0.17825312 | U43: =((H43+I43+J43+K43)/O43)*100 -> 0 | V43: =(N43/O43)*100 -> 0.71301248 | W43: =Q43+R43+S43+T43+U43+V43 -> 100 | X43: 0 | Y43: =P43-X43 -> 51.5625
...

Sheet ATTAVARA
A1: WARD NAME | B1: Booth | C1: TOTAL VOTERS | D1: No of Valid Votes Cast in favor of | L1: Total of Valid Votes | M1: No.Of Rejected votes | N1: NOTA | O1: Total | P1: TOTAL POLLING % | Q1: BJP% | R1: CONGRESS % | S1: JDS % | T1: AAP% | U1: TOTAL INDEPENDENT % | V1: NOTA% | W1: BJP V/S CONG(DIFF) | X1: BJP V/S OP | Y1: BOOTH CATEGORIZATION | Z1: POLLING STATION STATS | AA1: BJP/CONGRESS | AB1: Electors Total | AC1: Electors Polled | AD1: Male Total | AE1: Male Polled | AF1: Female Total | AG1: Female Polled | AH1: Hindus Total | AI1: Hindus Polled | AJ1: Muslims Total | AK1: Muslims Polled | AL1: Christians Total | AM1: Christian polled | AN1: MALE % | AO1: TOTAL MALE POLLED% | AP1: FEMALE % | AQ1: TOTAL FEMALE POLLED % | AR1: GENDER STATS | AS1: MEN POLLING V/S FEMALE POLLING | AT1: TOTAL HINDU% | AU1: TOTAL HINDU POLLED % | AV1: TOTAL MUSLIM % | AW1: TOTAL MUSLIM POLLED % | AX1: TOTAL CHRISTIAN % | AY1: TOTAL CHRISTIAN POLLED % | AZ1: MAJORITY VS MINORITY | BA1: POLLING MAJORITY VS MINORITY
D3: J.R.LOBO | E3: D.VEDAVYASA KAMATH | F3: S | G3: K.SANTHOSH KAMATH | H3: DHARMENDRA | I3: WINNY PINTO | J3: S | K3: K.S.PAI
A7: ATHAVARA | B7: 152 | C7: 694 | D7: 182 | E7: 268 | F7: 0 | G7: 0 | H7: 0 | I7: 1 | J7: 0 | K7: 0 | L7: 451 | M7: 0 | N7: 2 | O7: =D7+E7+F7+G7+H7+I7+J7+K7+N7 -> 453 | P7: =(O7/C7)*100 -> 65.273775 | Q7: =(E7/O7)*100 -> 59.161148 | R7: =(D7/O7)*100 -> 40.1766 | S7: =(F7/O7)*100 -> 0 | T7: =(G7/O7)*100 -> 0 | U7: =((H7+I7+J7+K7)/O7)*100 -> 0.22075055 | V7: =(N7/O7)*100 -> 0.4415011 | W7: =Q7-R7 -> 18.984547 | X7: =Q7-(R7+S7+T7+U7) -> 18.763797 | Y7: =IF(AND(W7<0,W7<=1),"LOST",IF(AND(W7>1,W7<=10),"NARROW",IF(AND(W7>10,W7<=40),"MEDIUM",IF(AND(W7>40,W7<=90),"STRONG","")))) -> MEDIUM | Z7: =IF(AND(P7<0,P7<=10),"WEAK",IF(AND(P7>10,P7<20),"BELOW AVG",IF(AND(P7>20,P7<=60),"MEDIUM",IF(AND(P7>60,P7<=90),"STRONG","")))) -> STRONG | AA7: =IF(Q7>R7,"BJP","CONGRESS") -> BJP | AB7: 694 | AD7: 305 | AF7: 389 | AH7: 573 | AJ7: 20 | AL7: 101 | AN7: =(AD7/AB7)*100 -> 43.948127 | AO7: =(AE7/AC7)*100 -> #DIV/0! | AP7: =(AF7/AB7)*100 -> 56.051873 | AQ7: =(AF7/AC7)*100 -> #DIV/0! | AR7: =IF(AN7>AP7,"MALE DOM","FEMALE DOM") -> FEMALE DOM | AS7: =IF(AO7>AP7,"MALE","FEMALE") -> #DIV/0! | AT7: =(AH7/AB7)*100 -> 82.564841 | AU7: =(AI7/AC7)*100 -> #DIV/0! | AV7: =(AJ7/AB7)*100 -> 2.8818444 | AW7: =(AK7/AC7)*100 -> #DIV/0! | AX7: =(AL7/AB7)*100 -> 14.553314 | AY7: =(AM7/AC7)*100 -> #DIV/0! | AZ7: =IF(AT7>(AV7+AX7),"HINDU","MINORITY") -> HINDU | BA7: =IF(AU7>(AW7+AY7),"HIND","MINORITY") -> #DIV/0!
B8: 151 | C8: 967 | D8: 149 | E8: 438 | F8: 2 | G8: 2 | H8: 0 | I8: 1 | J8: 0 | K8: 0 | L8: 592 | M8: 0 | N8: 3 | O8: =D8+E8+F8+G8+H8+I8+J8+K8+N8 -> 595 | P8: =(O8/C8)*100 -> 61.530507 | Q8: =(E8/O8)*100 -> 73.613445 | R8: =(D8/O8)*100 -> 25.042017 | S8: =(F8/O8)*100 -> 0.33613445 | T8: =(G8/O8)*100 -> 0.33613445 | U8: =((H8+I8+J8+K8)/O8)*100 -> 0.16806723 | V8: =(N8/O8)*100 -> 0.50420168 | W8: =Q8-R8 -> 48.571429 | X8: =Q8-(R8+S8+T8+U8) -> 47.731092 | Y8: =IF(AND(W8<0,W8<=1),"LOST",IF(AND(W8>1,W8<=10),"NARROW",IF(AND(W8>10,W8<=40),"MEDIUM",IF(AND(W8>40,W8<=90),"STRONG","")))) -> STRONG | Z8: =IF(AND(P8<0,P8<=10),"WEAK",IF(AND(P8>10,P8<20),"BELOW AVG",IF(AND(P8>20,P8<=60),"MEDIUM",IF(AND(P8>60,P8<=90),"STRONG","")))) -> STRONG | AA8: =IF(Q8>R8,"BJP","CONGRESS") -> BJP | AB8: 964 | AD8: 469 | AF8: 495 | AH8: 776 | AJ8: 25 | AL8: 163 | AN8: =(AD8/AB8)*100 -> 48.651452 | AO8: =(AE8/AC8)*100 -> #DIV/0! | AP8: =(AF8/AB8)*100 -> 51.348548 | AQ8: =(AF8/AC8)*100 -> #DIV/0! | AR8: =IF(AN8>AP8,"MALE DOM","FEMALE DOM") -> FEMALE DOM | AS8: =IF(AO8>AP8,"MALE","FEMALE") -> #DIV/0! | AT8: =(AH8/AB8)*100 -> 80.497925 | AU8: =(AI8/AC8)*100 -> #DIV/0! | AV8: =(AJ8/AB8)*100 -> 2.593361 | AW8: =(AK8/AC8)*100 -> #DIV/0! | AX8: =(AL8/AB8)*100 -> 16.908714 | AY8: =(AM8/AC8)*100 -> #DIV/0! | AZ8: =IF(AT8>(AV8+AX8),"HINDU","MINORITY") -> HINDU | BA8: =IF(AU8>(AW8+AY8),"HIND","MINORITY") -> #DIV/0!
B9: 242 | C9: 1008 | D9: 481 | E9: 174 | F9: 0 | G9: 0 | H9: 0 | I9: 1 | J9: 1 | K9: 0 | L9: 657 | M9: 0 | N9: 1 | O9: =D9+E9+F9+G9+H9+I9+J9+K9+N9 -> 658 | P9: =(O9/C9)*100 -> 65.277778 | Q9: =(E9/O9)*100 -> 26.443769 | R9: =(D9/O9)*100 -> 73.100304 | S9: =(F9/O9)*100 -> 0 | T9: =(G9/O9)*100 -> 0 | U9: =((H9+I9+J9+K9)/O9)*100 -> 0.30395137 | V9: =(N9/O9)*100 -> 0.15197568 | W9: =Q9-R9 -> -46.656535 | X9: =Q9-(R9+S9+T9+U9) -> -46.960486 | Y9: =IF(AND(W9<0,W9<=1),"LOST",IF(AND(W9>1,W9<=10),"NARROW",IF(AND(W9>10,W9<=40),"MEDIUM",IF(AND(W9>40,W9<=90),"STRONG","")))) -> LOST | Z9: =IF(AND(P9<0,P9<=10),"WEAK",IF(AND(P9>10,P9<20),"BELOW AVG",IF(AND(P9>20,P9<=60),"MEDIUM",IF(AND(P9>60,P9<=90),"STRONG","")))) -> STRONG | AA9: =IF(Q9>R9,"BJP","CONGRESS") -> CONGRESS | AB9: 1004 | AD9: 488 | AF9: 516 | AH9: 337 | AJ9: 617 | AL9: 50 | AN9: =(AD9/AB9)*100 -> 48.605578 | AO9: =(AE9/AC9)*100 -> #DIV/0! | AP9: =(AF9/AB9)*100 -> 51.394422 | AQ9: =(AF9/AC9)*100 -> #DIV/0! | AR9: =IF(AN9>AP9,"MALE DOM","FEMALE DOM") -> FEMALE DOM | AS9: =IF(AO9>AP9,"MALE","FEMALE") -> #DIV/0! | AT9: =(AH9/AB9)*100 -> 33.565737 | AU9: =(AI9/AC9)*100 -> #DIV/0! | AV9: =(AJ9/AB9)*100 -> 61.454183 | AW9: =(AK9/AC9)*100 -> #DIV/0! | AX9: =(AL9/AB9)*100 -> 4.9800797 | AY9: =(AM9/AC9)*100 -> #DIV/0! | AZ9: =IF(AT9>(AV9+AX9),"HINDU","MINORITY") -> MINORITY | BA9: =IF(AU9>(AW9+AY9),"HIND","MINORITY") -> #DIV/0!
B10: 243 | C10: 964 | D10: 254 | E10: 397 | F10: 3 | G10: 5 | H10: 1 | I10: 0 | J10: 0 | K10: 1 | L10: 661 | M10: 0 | N10: 5 | O10: =D10+E10+F10+G10+H10+I10+J10+K10+N10 -> 666 | P10: =(O10/C10)*100 -> 69.087137 | Q10: =(E10/O10)*100 -> 59.60961 | R10: =(D10/O10)*100 -> 38.138138 | S10: =(F10/O10)*100 -> 0.45045045 | T10: =(G10/O10)*100 -> 0.75075075 | U10: =((H10+I10+J10+K10)/O10)*100 -> 0.3003003 | V10: =(N10/O10)*100 -> 0.75075075 | W10: =Q10-R10 -> 21.471471 | X10: =Q10-(R10+S10+T10+U10) -> 19.96997 | Y10: =IF(AND(W10<0,W10<=1),"LOST",IF(AND(W10>1,W10<=10),"NARROW",IF(AND(W10>10,W10<=40),"MEDIUM",IF(AND(W10>40,W10<=90),"STRONG","")))) -> MEDIUM | Z10: =IF(AND(P10<0,P10<=10),"WEAK",IF(AND(P10>10,P10<20),"BELOW AVG",IF(AND(P10>20,P10<=60),"MEDIUM",IF(AND(P10>60,P10<=90),"STRONG","")))) -> STRONG | AA10: =IF(Q10>R10,"BJP","CONGRESS") -> BJP | AB10: 958 | AD10: 449 | AF10: 509 | AH10: 639 | AJ10: 256 | AL10: 63 | AN10: =(AD10/AB10)*100 -> 46.868476 | AO10: =(AE10/AC10)*100 -> #DIV/0! | AP10: =(AF10/AB10)*100 -> 53.131524 | AQ10: =(AF10/AC10)*100 -> #DIV/0! | AR10: =IF(AN10>AP10,"MALE DOM","FEMALE DOM") -> FEMALE DOM | AS10: =IF(AO10>AP10,"MALE","FEMALE") -> #DIV/0! | AT10: =(AH10/AB10)*100 -> 66.701461 | AU10: =(AI10/AC10)*100 -> #DIV/0! | AV10: =(AJ10/AB10)*100 -> 26.722338 | AW10: =(AK10/AC10)*100 -> #DIV/0! | AX10: =(AL10/AB10)*100 -> 6.5762004 | AY10: =(AM10/AC10)*100 -> #DIV/0! | AZ10: =IF(AT10>(AV10+AX10),"HINDU","MINORITY") -> HINDU | BA10: =IF(AU10>(AW10+AY10),"HIND","MINORITY") -> #DIV/0!
B11: 221 | C11: 1018 | D11: 320 | E11: 275 | F11: 4 | G11: 1 | H11: 0 | I11: 0 | J11: 1 | K11: 0 | L11: 601 | M11: 0 | N11: 2 | O11: =D11+E11+F11+G11+H11+I11+J11+K11+N11 -> 603 | P11: =(O11/C11)*100 -> 59.233792 | Q11: =(E11/O11)*100 -> 45.605307 | R11: =(D11/O11)*100 -> 53.067993 | S11: =(F11/O11)*100 -> 0.66334992 | T11: =(G11/O11)*100 -> 0.16583748 | U11: =((H11+I11+J11+K11)/O11)*100 -> 0.16583748 | V11: =(N11/O11)*100 -> 0.33167496 | W11: =Q11-R11 -> -7.4626866 | X11: =Q11-(R11+S11+T11+U11) -> -8.4577114 | Y11: =IF(AND(W11<0,W11<=1),"LOST",IF(AND(W11>1,W11<=10),"NARROW",IF(AND(W11>10,W11<=40),"MEDIUM",IF(AND(W11>40,W11<=90),"STRONG","")))) -> LOST | Z11: =IF(AND(P11<0,P11<=10),"WEAK",IF(AND(P11>10,P11<20),"BELOW AVG",IF(AND(P11>20,P11<=60),"MEDIUM",IF(AND(P11>60,P11<=90),"STRONG","")))) -> MEDIUM | AA11: =IF(Q11>R11,"BJP","CONGRESS") -> CONGRESS | AB11: 1014 | AD11: 502 | AF11: 512 | AH11: 498 | AJ11: 385 | AL11: 131 | AN11: =(AD11/AB11)*100 -> 49.506903 | AO11: =(AE11/AC11)*100 -> #DIV/0! | AP11: =(AF11/AB11)*100 -> 50.493097 | AQ11: =(AF11/AC11)*100 -> #DIV/0! | AR11: =IF(AN11>AP11,"MALE DOM","FEMALE DOM") -> FEMALE DOM | AS11: =IF(AO11>AP11,"MALE","FEMALE") -> #DIV/0! | AT11: =(AH11/AB11)*100 -> 49.112426 | AU11: =(AI11/AC11)*100 -> #DIV/0! | AV11: =(AJ11/AB11)*100 -> 37.968442 | AW11: =(AK11/AC11)*100 -> #DIV/0! | AX11: =(AL11/AB11)*100 -> 12.919132 | AY11: =(AM11/AC11)*100 -> #DIV/0! | AZ11: =IF(AT11>(AV11+AX11),"HINDU","MINORITY") -> MINORITY | BA11: =IF(AU11>(AW11+AY11),"HIND","MINORITY") -> #DIV/0!
B12: 222 | C12: 1092 | D12: 332 | E12: 330 | F12: 2 | G12: 5 | H12: 0 | I12: 1 | J12: 2 | K12: 0 | L12: 672 | M12: 0 | N12: 3 | O12: =D12+E12+F12+G12+H12+I12+J12+K12+N12 -> 675 | P12: =(O12/C12)*100 -> 61.813187 | Q12: =(E12/O12)*100 -> 48.888889 | R12: =(D12/O12)*100 -> 49.185185 | S12: =(F12/O12)*100 -> 0.2962963 | T12: =(G12/O12)*100 -> 0.74074074 | U12: =((H12+I12+J12+K12)/O12)*100 -> 0.44444444 | V12: =(N12/O12)*100 -> 0.44444444 | W12: =Q12-R12 -> -0.2962963 | X12: =Q12-(R12+S12+T12+U12) -> -1.7777778 | Y12: =IF(AND(W12<0,W12<=1),"LOST",IF(AND(W12>1,W12<=10),"NARROW",IF(AND(W12>10,W12<=40),"MEDIUM",IF(AND(W12>40,W12<=90),"STRONG","")))) -> LOST | Z12: =IF(AND(P12<0,P12<=10),"WEAK",IF(AND(P12>10,P12<20),"BELOW AVG",IF(AND(P12>20,P12<=60),"MEDIUM",IF(AND(P12>60,P12<=90),"STRONG","")))) -> STRONG | AA12: =IF(Q12>R12,"BJP","CONGRESS") -> CONGRESS | AB12: 1091 | AD12: 515 | AF12: 576 | AH12: 613 | AJ12: 240 | AL12: 238 | AN12: =(AD12/AB12)*100 -> 47.2044 | AO12: =(AE12/AC12)*100 -> #DIV/0! | AP12: =(AF12/AB12)*100 -> 52.7956 | AQ12: =(AF12/AC12)*100 -> #DIV/0! | AR12: =IF(AN12>AP12,"MALE DOM","FEMALE DOM") -> FEMALE DOM | AS12: =IF(AO12>AP12,"MALE","FEMALE") -> #DIV/0! | AT12: =(AH12/AB12)*100 -> 56.186984 | AU12: =(AI12/AC12)*100 -> #DIV/0! | AV12: =(AJ12/AB12)*100 -> 21.998167 | AW12: =(AK12/AC12)*100 -> #DIV/0! | AX12: =(AL12/AB12)*100 -> 21.814849 | AY12: =(AM12/AC12)*100 -> #DIV/0! | AZ12: =IF(AT12>(AV12+AX12),"HINDU","MINORITY") -> HINDU | BA12: =IF(AU12>(AW12+AY12),"HIND","MINORITY") -> #DIV/0!
B13: 153 | C13: 883 | D13: 189 | E13: 397 | F13: 1 | G13: 3 | H13: 0 | I13: 0 | J13: 0 | K13: 1 | L13: 591 | M13: 0 | N13: 4 | O13: =D13+E13+F13+G13+H13+I13+J13+K13+N13 -> 595 | P13: =(O13/C13)*100 -> 67.383918 | Q13: =(E13/O13)*100 -> 66.722689 | R13: =(D13/O13)*100 -> 31.764706 | S13: =(F13/O13)*100 -> 0.16806723 | T13: =(G13/O13)*100 -> 0.50420168 | U13: =((H13+I13+J13+K13)/O13)*100 -> 0.16806723 | V13: =(N13/O13)*100 -> 0.67226891 | W13: =Q13-R13 -> 34.957983 | X13: =Q13-(R13+S13+T13+U13) -> 34.117647 | Y13: =IF(AND(W13<0,W13<=1),"LOST",IF(AND(W13>1,W13<=10),"NARROW",IF(AND(W13>10,W13<=40),"MEDIUM",IF(AND(W13>40,W13<=90),"STRONG","")))) -> MEDIUM | Z13: =IF(AND(P13<0,P13<=10),"WEAK",IF(AND(P13>10,P13<20),"BELOW AVG",IF(AND(P13>20,P13<=60),"MEDIUM",IF(AND(P13>60,P13<=90),"STRONG","")))) -> STRONG | AA13: =IF(Q13>R13,"BJP","CONGRESS") -> BJP | AB13: 880 | AD13: 417 | AF13: 462 | AH13: 722 | AJ13: 41 | AL13: 117 | AN13: =(AD13/AB13)*100 -> 47.386364 | AO13: =(AE13/AC13)*100 -> #DIV/0! | AP13: =(AF13/AB13)*100 -> 52.5 | AQ13: =(AF13/AC13)*100 -> #DIV/0! | AR13: =IF(AN13>AP13,"MALE DOM","FEMALE DOM") -> FEMALE DOM | AS13: =IF(AO13>AP13,"MALE","FEMALE") -> #DIV/0! | AT13: =(AH13/AB13)*100 -> 82.045455 | AU13: =(AI13/AC13)*100 -> #DIV/0! | AV13: =(AJ13/AB13)*100 -> 4.6590909 | AW13: =(AK13/AC13)*100 -> #DIV/0! | AX13: =(AL13/AB13)*100 -> 13.295455 | AY13: =(AM13/AC13)*100 -> #DIV/0! | AZ13: =IF(AT13>(AV13+AX13),"HINDU","MINORITY") -> HINDU | BA13: =IF(AU13>(AW13+AY13),"HIND","MINORITY") -> #DIV/0!
C14: =SUM(C7:C13) -> 6626 | D14: =SUM(D7:D13) -> 1907 | E14: =SUM(E7:E13) -> 2279 | F14: =SUM(F7:F13) -> 12 | G14: =SUM(G7:G13) -> 16 | H14: =SUM(H7:H13) -> 1 | I14: =SUM(I7:I13) -> 4 | J14: =SUM(J7:J13) -> 4 | ... O14: =SUM(O7:O13) -> 4245 | P14: =AVERAGE(P7:P13) -> 64.228585 | Q14: =AVERAGE(Q7:Q13) -> 54.292122 | R14: =AVERAGE(R7:R13) -> 44.353563 | S14: =AVERAGE(S7:S13) -> 0.27347119 | T14: =AVERAGE(T7:T13) -> 0.3568093 | U14: =AVERAGE(U7:U13) -> 0.2530598 | V14: =AVERAGE(V7:V13) -> 0.47097393 | W14: =AVERAGE(W7:W13) -> 9.938559 | X14: =AVERAGE(X7:X13) -> 9.0552187 | Y14: =IF(AND(W14<0,W14<=1),"LOST",IF(AND(W14>1,W14<=10),"NARROW",IF(AND(W14>10,W14<=40),"MEDIUM",IF(AND(W14>40,W14<=90),"STRONG","")))) -> NARROW | Z14: =IF(AND(P14<0,P14<=10),"WEAK",IF(AND(P14>10,P14<20),"BELOW AVG",IF(AND(P14>20,P14<=60),"MEDIUM",IF(AND(P14>60,P14<=90),"STRONG","")))) -> STRONG | AA14: =IF(Q14>R14,"BJP","CONGRESS") -> BJP | AB14: =SUM(AB7:AB13) -> 6605 | AD14: =SUM(AD7:AD13) -> 3145 | AF14: =SUM(AF7:AF13) -> 3459 | AH14: =SUM(AH7:AH13) -> 4158 | AJ14: =SUM(AJ7:AJ13) -> 1584 | AL14: =SUM(AL7:AL13) -> 863 | AN14: =AVERAGE(AN7:AN13) -> 47.453043 | AO14: =AVERAGE(AN14) -> 47.453043 | AP14: =AVERAGE(AP7:AP13) -> 52.530723 | AQ14: =AVERAGE(AN14:AP14) -> 49.145603 | AR14: =IF(AN14>AP14,"MALE DOM","FEMALE DOM") -> FEMALE DOM | AS14: =IF(AO14>AP14,"MALE","FEMALE") -> FEMALE | AT14: =AVERAGE(AT7:AT13) -> 64.382119 | AV14: =AVERAGE(AV7:AV13) -> 22.611061 | AZ14: =IF(AT14>(AV14+AX14),"HINDU","MINORITY") -> HINDU | BA14: =IF(AU14>(AW14+AY14),"HIND","MINORITY") -> MINORITY
B18: TOTAL BOOTH 7 | G18: BOOTH WISE CATEGORIZATION | L18: COMPARITIVE ANALYSIS
B20: BJP WON | E20: =COUNTIF(AA7:AA13,"BJP") -> 4 | G20: NARROW | J20: =COUNTIF(Y7:Y13,"NARROW") -> 0 | L20: BJP %(2018) | O20: ='ATTAVARA-18'!E11 -> 48.638198 | P20: BJP%(2023) | S20: =Q14 -> 54.292122
G22: MEDIUM | J22: =COUNTIF(Y7:Y13,"MEDIUM") -> 3 | L22: CONGRESS %(2018) | O22: ='ATTAVARA-18'!G11 -> 48.297252 | P22: CONGRESS%(2023) | S22: =R14 -> 44.353563
B23: CONGRESS WON | E23: =COUNTIF(AA7:AA13,"CONGRESS") -> 3
G24: STRONG | J24: =COUNTIF(Y7:Y13,"STRONG") -> 1 | L24: TOTAL POLLED (2018) | O24: ='ATTAVARA-18'!C11 -> 5252 | P24: TOTAL POLLED (2023) | S24: =O14 -> 4245
G26: LOST | J26: =COUNTIF(Y7:Y13,"LOST") -> 3 | L26: TOTAL GAIN/LOSS | O26: =O20-O22 -> 0.34094569 | P26: TOTAL GAIN/LOSS | S26: =S20-S22 -> 9.938559
L28: BJP%(18/23) | O28: =S20-O20 -> 5.6539245
L30: CONGRESS%(18/23) | O30: =S22-O22 -> -3.9436888
L32: INCREASE/DECREASE | O32: =IF(O28>O30,"INCREASE","DECREASE") -> INCREASE
L34: TWO BOOTHS HAS BEEN ADDED IN 2023

Sheet ATTAVARA-18
A2: BOOTH NO | B2: PS ADDRESS | C2: TOTAL POLLED | D2: BJP | E2: BJP % | F2: INC | G2: INC % | H2: JDS | I2: JDS % | J2: CPI | K2: CPI% | L2: MALE VOTERS | M2: FEMALE VOTERS | N2: TOTAL VOTERS | O2: TOTAL POLLED | P2: PERCENTAGE POLLING | Q2: HINDU | R2: HINDU PERCENTAGE IN THE CONSTITUENCY | S2: HINDU NOT POLLED | T2: % of HINDU NON VOTERS | U2: HINDU POLLED | V2: % OF HINDU VOTERS | W2: others | X2: OTHERS % | Y2: others NOT POLLED | Z2: % OF OTHERS NOT POLLED | AA2: others polled | AB2: % | AD2: BOOTH STATUS(POOLING) | AE2: HINDU POPULATION STATUS | AF2: OTHERS POPULATION STATUS | AG2: GENDER RATIO | AH2: ratio of comparision non voters | AI2: VOTE TRANSITION | AJ2: WIN STATUS
A3: 138 | B3: Dakshina Kannad Zilla Panchayath Lower PrimarySchool,Babugudde Attavar (Middle portion ) | C3: 625 | D3: 438 | E3: =(D3/C3)*100 -> 70.08 | F3: 172 | G3: =(F3/C3)*100 -> 27.52 | H3: 4 | I3: =(H3/C3)*100 -> 0.64 | J3: 6 | K3: =(J3/C3)*100 -> 0.96 | L3: 454 | M3: 471 | N3: =L3+M3 -> 925 | O3: 625 | P3: =O3/N3*100 -> 67.567568 | Q3: 765 | R3: =(Q3/N3)*100 -> 82.702703 | S3: =Q3-U3 -> 247 | T3: =(S3/Q3)*100 -> 32.287582 | U3: 518 | V3: =IFERROR(U3/Q3*100,0) -> 67.712418 | W3: =925-765 -> 160 | X3: =100-R3 -> 17.297297 | Y3: =W3-AA3 -> 53 | Z3: =(Y3/W3)*100 -> 33.125 | AA3: =625-518 -> 107 | AB3: =IFERROR(AA3/W3*100,0) -> 66.875 | AC3: =U3+AA3 -> 625 | AD3: =IF(P3>80,"EXCELLENT",IF(P3>70,"STRONG",IF(P3>60,"AVG",IF(P3>50,"WEAK",IF(P3<50,"VLOW"))))) -> AVG | AE3: =IF(R3>80,"EXCELLENT",IF(R3>70,"STRONG",IF(R3>60,"AVG",IF(R3>50,"WEAK",IF(R3<50,"VLOW"))))) -> EXCELLENT | AF3: =IF(X3>80,"EXCELLENT",IF(X3>70,"STRONG",IF(X3>60,"AVG",IF(X3>50,"WEAK",IF(X3<50,"VLOW"))))) -> VLOW | AG3: =IF(M3>L3,"FEMALE DOM","MEN") -> FEMALE DOM | AH3: =IF(T3>Z3,"H","O") -> O | AI3: =E3-G3 -> 42.56 | AJ3: =IF(E3>G3,"BJP GAIN","CONGRESSGAIN") -> BJP GAIN
A4: 139 | B4: Dakshina Kannada Zilla PanchayathLowerPrimarySchool,Babugudde Attavara(West Portion ) | C4: 515 | D4: 283 | E4: =(D4/C4)*100 -> 54.951456 | F4: 218 | G4: =(F4/C4)*100 -> 42.330097 | H4: 1 | I4: =(H4/C4)*100 -> 0.19417476 | J4: 6 | K4: =(J4/C4)*100 -> 1.1650485 | L4: 310 | M4: 415 | N4: =L4+M4 -> 725 | O4: 515 | P4: =O4/N4*100 -> 71.034483 | Q4: 552 | R4: =(Q4/N4)*100 -> 76.137931 | S4: =Q4-U4 -> 121 | T4: =(S4/Q4)*100 -> 21.92029 | U4: 431 | V4: =IFERROR(U4/Q4*100,0) -> 78.07971 | W4: 173 | X4: =100-R4 -> 23.862069 | Y4: =W4-AA4 -> 107 | Z4: =(Y4/W4)*100 -> 61.849711 | AA4: 66 | AB4: =IFERROR(AA4/W4*100,0) -> 38.150289 | AC4: =U4+AA4 -> 497 | AD4: =IF(P4>80,"EXCELLENT",IF(P4>70,"STRONG",IF(P4>60,"AVG",IF(P4>50,"WEAK",IF(P4<50,"VLOW"))))) -> STRONG | AE4: =IF(R4>80,"EXCELLENT",IF(R4>70,"STRONG",IF(R4>60,"AVG",IF(R4>50,"WEAK",IF(R4<50,"VLOW"))))) -> STRONG | AF4: =IF(X4>80,"EXCELLENT",IF(X4>70,"STRONG",IF(X4>60,"AVG",IF(X4>50,"WEAK",IF(X4<50,"VLOW"))))) -> VLOW | AG4: =IF(M4>L4,"FEMALE DOM","MEN") -> FEMALE DOM | AH4: =IF(T4>Z4,"H","O") -> O | AI4: =E4-G4 -> 12.621359 | AJ4: =IF(E4>G4,"BJP GAIN","CONGRESSGAIN") -> BJP GAIN
A5: 140 | B5: Kudmal Ranga Rao Samaja Bhavana Babugudda Attavara(South Portion) | C5: 611 | D5: 398 | E5: =(D5/C5)*100 -> 65.139116 | F5: 193 | G5: =(F5/C5)*100 -> 31.587561 | H5: 4 | I5: =(H5/C5)*100 -> 0.65466448 | J5: 11 | K5: =(J5/C5)*100 -> 1.8003273 | L5: 429 | M5: 482 | N5: =L5+M5 -> 911 | O5: 611 | P5: =O5/N5*100 -> 67.069155 | R5: =(Q5/N5)*100 -> 0 | S5: =Q5-U5 -> 0 | T5: =(S5/Q5)*100 -> #DIV/0! | V5: =IFERROR(U5/Q5*100,0) -> 0 | X5: =100-R5 -> 100 | Y5: =W5-AA5 -> 0 | Z5: =(Y5/W5)*100 -> #DIV/0! | AB5: =IFERROR(AA5/W5*100,0) -> 0 | AC5: =U5+AA5 -> 0 | AD5: =IF(P5>80,"EXCELLENT",IF(P5>70,"STRONG",IF(P5>60,"AVG",IF(P5>50,"WEAK",IF(P5<50,"VLOW"))))) -> AVG | AE5: =IF(R5>80,"EXCELLENT",IF(R5>70,"STRONG",IF(R5>60,"AVG",IF(R5>50,"WEAK",IF(R5<50,"VLOW"))))) -> VLOW | AF5: =IF(X5>80,"EXCELLENT",IF(X5>70,"STRONG",IF(X5>60,"AVG",IF(X5>50,"WEAK",IF(X5<50,"VLOW"))))) -> EXCELLENT | AG5: =IF(M5>L5,"FEMALE DOM","MEN") -> FEMALE DOM | AH5: =IF(T5>Z5,"H","O") -> #DIV/0! | AI5: =E5-G5 -> 33.551555 | AJ5: =IF(E5>G5,"BJP GAIN","CONGRESSGAIN") -> BJP GAIN
A6: 197 | B6: Cascia High School, Jeppu (North wing ) | C6: 986 | D6: 428 | E6: =(D6/C6)*100 -> 43.407708 | F6: 524 | G6: =(F6/C6)*100 -> 53.144016 | H6: 6 | I6: =(H6/C6)*100 -> 0.60851927 | J6: 11 | K6: =(J6/C6)*100 -> 1.1156187 | L6: 734 | M6: 781 | N6: =L6+M6 -> 1515 | O6: 986 | P6: =O6/N6*100 -> 65.082508 | R6: =(Q6/N6)*100 -> 0 | S6: =Q6-U6 -> 0 | T6: =(S6/Q6)*100 -> #DIV/0! | V6: =IFERROR(U6/Q6*100,0) -> 0 | X6: =100-R6 -> 100 | Y6: =W6-AA6 -> 0 | Z6: =(Y6/W6)*100 -> #DIV/0! | AB6: =IFERROR(AA6/W6*100,0) -> 0 | AC6: =U6+AA6 -> 0 | AD6: =IF(P6>80,"EXCELLENT",IF(P6>70,"STRONG",IF(P6>60,"AVG",IF(P6>50,"WEAK",IF(P6<50,"VLOW"))))) -> AVG | AE6: =IF(R6>80,"EXCELLENT",IF(R6>70,"STRONG",IF(R6>60,"AVG",IF(R6>50,"WEAK",IF(R6<50,"VLOW"))))) -> VLOW | AF6: =IF(X6>80,"EXCELLENT",IF(X6>70,"STRONG",IF(X6>60,"AVG",IF(X6>50,"WEAK",IF(X6<50,"VLOW"))))) -> EXCELLENT | AG6: =IF(M6>L6,"FEMALE DOM","MEN") -> FEMALE DOM | AH6: =IF(T6>Z6,"H","O") -> #DIV/0! | AI6: =G6-E6 -> 9.7363083 | AJ6: =IF(E6>G6,"BJP GAIN","CONGRESSGAIN") -> CONGRESSGAIN
A7: 198 | B7: Cascia High School, Jeppu (South wing ) | C7: 588 | D7: 223 | E7: =(D7/C7)*100 -> 37.92517 | F7: 337 | G7: =(F7/C7)*100 -> 57.312925 | H7: 4 | I7: =(H7/C7)*100 -> 0.68027211 | J7: 3 | K7: =(J7/C7)*100 -> 0.51020408 | L7: 461 | M7: 474 | N7: =L7+M7 -> 935 | O7: 588 | P7: =O7/N7*100 -> 62.887701 | R7: =(Q7/N7)*100 -> 0 | S7: =Q7-U7 -> 0 | T7: =(S7/Q7)*100 -> #DIV/0! | V7: =IFERROR(U7/Q7*100,0) -> 0 | X7: =100-R7 -> 100 | Y7: =W7-AA7 -> 0 | Z7: =(Y7/W7)*100 -> #DIV/0! | AB7: =IFERROR(AA7/W7*100,0) -> 0 | AC7: =U7+AA7 -> 0 | AD7: =IF(P7>80,"EXCELLENT",IF(P7>70,"STRONG",IF(P7>60,"AVG",IF(P7>50,"WEAK",IF(P7<50,"VLOW"))))) -> AVG | AE7: =IF(R7>80,"EXCELLENT",IF(R7>70,"STRONG",IF(R7>60,"AVG",IF(R7>50,"WEAK",IF(R7<50,"VLOW"))))) -> VLOW | AF7: =IF(X7>80,"EXCELLENT",IF(X7>70,"STRONG",IF(X7>60,"AVG",IF(X7>50,"WEAK",IF(X7<50,"VLOW"))))) -> EXCELLENT | AG7: =IF(M7>L7,"FEMALE DOM","MEN") -> FEMALE DOM | AH7: =IF(T7>Z7,"H","O") -> #DIV/0! | AI7: =G7-E7 -> 19.387755 | AJ7: =IF(E7>G7,"BJP GAIN","CONGRESSGAIN") -> CONGRESSGAIN
A8: 199 | B8: Saint Ritas Kannada Medium Aided Higher Primary School, Jeppu (North wing ) | C8: 716 | D8: 303 | E8: =(D8/C8)*100 -> 42.318436 | F8: 392 | G8: =(F8/C8)*100 -> 54.748603 | H8: 1 | I8: =(H8/C8)*100 -> 0.1396648 | J8: 8 | K8: =(J8/C8)*100 -> 1.1173184 | L8: 491 | M8: 574 | N8: =L8+M8 -> 1065 | O8: 716 | P8: =O8/N8*100 -> 67.230047 | R8: =(Q8/N8)*100 -> 0 | S8: =Q8-U8 -> 0 | T8: =(S8/Q8)*100 -> #DIV/0! | V8: =IFERROR(U8/Q8*100,0) -> 0 | X8: =100-R8 -> 100 | Y8: =W8-AA8 -> 0 | Z8: =(Y8/W8)*100 -> #DIV/0! | AB8: =IFERROR(AA8/W8*100,0) -> 0 | AC8: =U8+AA8 -> 0 | AD8: =IF(P8>80,"EXCELLENT",IF(P8>70,"STRONG",IF(P8>60,"AVG",IF(P8>50,"WEAK",IF(P8<50,"VLOW"))))) -> AVG | AE8: =IF(R8>80,"EXCELLENT",IF(R8>70,"STRONG",IF(R8>60,"AVG",IF(R8>50,"WEAK",IF(R8<50,"VLOW"))))) -> VLOW | AF8: =IF(X8>80,"EXCELLENT",IF(X8>70,"STRONG",IF(X8>60,"AVG",IF(X8>50,"WEAK",IF(X8<50,"VLOW"))))) -> EXCELLENT | AG8: =IF(M8>L8,"FEMALE DOM","MEN") -> FEMALE DOM | AH8: =IF(T8>Z8,"H","O") -> #DIV/0! | AI8: =G8-E8 -> 12.430168 | AJ8: =IF(E8>G8,"BJP GAIN","CONGRESSGAIN") -> CONGRESSGAIN
A9: 200 | B9: Saint Retas Kannada Medium Aided Higher Primary School, Jeppu (Middle Wing ) | C9: 561 | D9: 248 | E9: =(D9/C9)*100 -> 44.206774 | F9: 298 | G9: =(F9/C9)*100 -> 53.11943 | H9: 8 | I9: =(H9/C9)*100 -> 1.426025 | J9: 2 | K9: =(J9/C9)*100 -> 0.35650624 | L9: 421 | M9: 473 | N9: =L9+M9 -> 894 | O9: 561 | P9: =O9/N9*100 -> 62.751678 | R9: =(Q9/N9)*100 -> 0 | S9: =Q9-U9 -> 0 | T9: =(S9/Q9)*100 -> #DIV/0! | V9: =IFERROR(U9/Q9*100,0) -> 0 | X9: =100-R9 -> 100 | Y9: =W9-AA9 -> 0 | Z9: =(Y9/W9)*100 -> #DIV/0! | AB9: =IFERROR(AA9/W9*100,0) -> 0 | AC9: =U9+AA9 -> 0 | AD9: =IF(P9>80,"EXCELLENT",IF(P9>70,"STRONG",IF(P9>60,"AVG",IF(P9>50,"WEAK",IF(P9<50,"VLOW"))))) -> AVG | AE9: =IF(R9>80,"EXCELLENT",IF(R9>70,"STRONG",IF(R9>60,"AVG",IF(R9>50,"WEAK",IF(R9<50,"VLOW"))))) -> VLOW | AF9: =IF(X9>80,"EXCELLENT",IF(X9>70,"STRONG",IF(X9>60,"AVG",IF(X9>50,"WEAK",IF(X9<50,"VLOW"))))) -> EXCELLENT | AG9: =IF(M9>L9,"FEMALE DOM","MEN") -> FEMALE DOM | AH9: =IF(T9>Z9,"H","O") -> #DIV/0! | AI9: =G9-E9 -> 8.912656 | AJ9: =IF(E9>G9,"BJP GAIN","CONGRESSGAIN") -> CONGRESSGAIN
A10: 217 | B10: Dakshina Kannada Zilla Panchayath Higher Primary School, Mahakalipadpu (Room No 3 Middle Portion) | C10: 650 | D10: 202 | E10: =(D10/C10)*100 -> 31.076923 | F10: 433 | G10: =(F10/C10)*100 -> 66.615385 | H10: 3 | I10: =(H10/C10)*100 -> 0.46153846 | J10: 1 | K10: =(J10/C10)*100 -> 0.15384615 | L10: 500 | M10: 522 | N10: =L10+M10 -> 1022 | O10: 650 | P10: =O10/N10*100 -> 63.600783 | R10: =(Q10/N10)*100 -> 0 | S10: =Q10-U10 -> 0 | T10: =(S10/Q10)*100 -> #DIV/0! | V10: =IFERROR(U10/Q10*100,0) -> 0 | X10: =100-R10 -> 100 | Y10: =W10-AA10 -> 0 | Z10: =(Y10/W10)*100 -> #DIV/0! | AB10: =IFERROR(AA10/W10*100,0) -> 0 | AC10: =U10+AA10 -> 0 | AD10: =IF(P10>80,"EXCELLENT",IF(P10>70,"STRONG",IF(P10>60,"AVG",IF(P10>50,"WEAK",IF(P10<50,"VLOW"))))) -> AVG | AE10: =IF(R10>80,"EXCELLENT",IF(R10>70,"STRONG",IF(R10>60,"AVG",IF(R10>50,"WEAK",IF(R10<50,"VLOW"))))) -> VLOW | AF10: =IF(X10>80,"EXCELLENT",IF(X10>70,"STRONG",IF(X10>60,"AVG",IF(X10>50,"WEAK",IF(X10<50,"VLOW"))))) -> EXCELLENT | AG10: =IF(M10>L10,"FEMALE DOM","MEN") -> FEMALE DOM | AH10: =IF(T10>Z10,"H","O") -> #DIV/0! | AI10: =G10-E10 -> 35.538462 | AJ10: =IF(E10>G10,"BJP GAIN","CONGRESSGAIN") -> CONGRESSGAIN
C11: =SUM(C3:C10) -> 5252 | D11: =SUM(D3:D10) -> 2523 | E11: =AVERAGE(E3:E10) -> 48.638198 | F11: =SUM(F3:F10) -> 2567 | G11: =AVERAGE(G3:G10) -> 48.297252 | H11: =SUM(H3:H10) -> 31 | I11: =AVERAGE(I3:I10) -> 0.60060736 | J11: =SUM(J3:J10) -> 48 | K11: =AVERAGE(K3:K10) -> 0.89735868 | N11: =SUM(N3:N10) -> 7992 | R11: =(Q11/N11)*100 -> 0 | X11: =100-R11 -> 100 | AE11: =IF(R11>80,"EXCELLENT",IF(R11>70,"STRONG",IF(R11>60,"AVG",IF(R11>50,"WEAK",IF(R11<50,"VLOW"))))) -> VLOW | AF11: =IF(X11>80,"EXCELLENT",IF(X11>70,"STRONG",IF(X11>60,"AVG",IF(X11>50,"WEAK",IF(X11<50,"VLOW"))))) -> EXCELLENT | AI11: =G11-E11 -> -0.34094569 | AJ11: =IF(E11>G11,"BJP GAIN","CONGRESSGAIN") -> BJP GAIN

Sheet ALAPE-S
A1: WARD NAME | B1: Booth | C1: TOTAL VOTERS | D1: No of Valid Votes Cast in favor of | L1: Total of Valid Votes | M1: No.Of Rejected votes | N1: NOTA | O1: Total | P1: TOTAL POLLING % | Q1: BJP% | R1: CONGRESS % | S1: JDS % | T1: AAP% | U1: TOTAL INDEPENDENT % | V1: NOTA% | W1: BJP V/S CONG | X1: BJP V/S OTHERPARTY | Y1: BOOTH STATS | Z1: POLLING BOOTH STATS | AA1: BJP/CONGRESS | AB1: Electors Total | AC1: Electors Polled | AD1: Male Total | AE1: Male Polled | AF1: Female Total | AG1: Female Polled | AH1: Hindus Total | AI1: Hindus Polled | AJ1: Muslims Total | AK1: Muslims Polled | AL1: Christians Total | AM1: Christian polled | AN1: MALE % | AO1: TOTAL MALE POLLED% | AP1: FEMALE % | AQ1: TOTAL FEMALE POLLED % | AR1: GENDER STATS | AS1: MEN POLLING V/S FEMALE POLLING | AT1: TOTAL HINDU% | AU1: TOTAL HINDU POLLED % | AV1: TOTAL MUSLIM % | AW1: TOTAL MUSLIM POLLED % | AX1: TOTAL CHRISTIAN % | AY1: TOTAL CHRISTIAN POLLED % | AZ1: MAJORITY VS MINORITY | BA1: POLLING MAJORITY VS MINORITY
D3: J.R.LOBO | E3: D.VEDAVYASA KAMATH | F3: S | G3: K.SANTHOSH KAMATH | H3: DHARMENDRA | I3: WINNY PINTO | J3: S | K3: K.S.PAI
A7: ALAPE SOUTH | B7: 188 | C7: 1077 | D7: 250 | E7: 476 | F7: 2 | G7: 0 | H7: 0 | I7: 0 | J7: 0 | K7: 1 | L7: 729 | M7: 0 | N7: 4 | O7: =D7+E7+F7+G7+H7+I7+J7+K7+N7 -> 733 | P7: =(O7/C7)*100 -> 68.059424 | Q7: =(E7/O7)*100 -> 64.938608 | R7: =(D7/O7)*100 -> 34.106412 | S7: =(F7/O7)*100 -> 0.2728513 | T7: =(G7/O7)*100 -> 0 | U7: =((H7+I7+J7+K7)/O7)*100 -> 0.13642565 | V7: =(N7/O7)*100 -> 0.54570259 | W7: =Q7-R7 -> 30.832196 | X7: =Q7-(R7+S7+T7+U7) -> 30.42292 | Y7: =IF(AND(W7<0,W7<=1),"LOST",IF(AND(W7>1,W7<=10),"NARROW",IF(AND(W7>10,W7<=40),"MEDIUM",IF(AND(W7>40,W7<=90),"STRONG","")))) -> MEDIUM | Z7: =IF(AND(P7<0,P7<=10),"WEAK",IF(AND(P7>10,P7<20),"BELOW AVG",IF(AND(P7>20,P7<=60),"MEDIUM",IF(AND(P7>60,P7<=90),"STRONG","")))) -> STRONG | AA7: =IF(Q7>R7,"BJP","CONGRESS") -> BJP | AB7: 1068 | AC7: 725 | AD7: 511 | AE7: 344 | AF7: 556 | AG7: 381 | AH7: 778 | AI7: 565 | AJ7: 59 | AK7: 27 | AL7: 231 | AM7: 133 | AN7: =(AD7/AB7)*100 -> 47.846442 | AO7: =(AE7/AC7)*100 -> 47.448276 | AP7: =(AF7/AB7)*100 -> 52.059925 | AQ7: =(AG7/AC7)*100 -> 52.551724 | AR7: =IF(AN7>AP7,"MALE DOM","FEMALE DOM") -> FEMALE DOM | AS7: =IF(AO7>AP7,"MALE","FEMALE") -> FEMALE | AT7: =(AH7/AB7)*100 -> 72.846442 | AU7: =(AI7/AC7)*100 -> 77.931034 | AV7: =(AJ7/AB7)*100 -> 5.5243446 | AW7: =(AK7/AC7)*100 -> 3.7241379 | AX7: =(AL7/AB7)*100 -> 21.629213 | AY7: =(AM7/AC7)*100 -> 18.344828 | AZ7: =IF(AT7>(AV7+AX7),"HINDU","MINORITY") -> HINDU | BA7: =IF(AU7>(AW7+AY7),"HIND","MINORITY") -> HIND
B8: 187 | C8: 1008 | D8: 135 | E8: 583 | F8: 3 | G8: 7 | H8: 0 | I8: 0 | J8: 0 | K8: 1 | L8: 729 | M8: 0 | N8: 4 | O8: =D8+E8+F8+G8+H8+I8+J8+K8+N8 -> 733 | P8: =(O8/C8)*100 -> 72.718254 | Q8: =(E8/O8)*100 -> 79.536153 | R8: =(D8/O8)*100 -> 18.417462 | S8: =(F8/O8)*100 -> 0.40927694 | T8: =(G8/O8)*100 -> 0.95497954 | U8: =((H8+I8+J8+K8)/O8)*100 -> 0.13642565 | V8: =(N8/O8)*100 -> 0.54570259 | W8: =Q8-R8 -> 61.11869 | X8: =Q8-(R8+S8+T8+U8) -> 59.618008 | Y8: =IF(AND(W8<0,W8<=1),"LOST",IF(AND(W8>1,W8<=10),"NARROW",IF(AND(W8>10,W8<=40),"MEDIUM",IF(AND(W8>40,W8<=90),"STRONG","")))) -> STRONG | Z8: =IF(AND(P8<0,P8<=10),"WEAK",IF(AND(P8>10,P8<20),"BELOW AVG",IF(AND(P8>20,P8<=60),"MEDIUM",IF(AND(P8>60,P8<=90),"STRONG","")))) -> STRONG | AA8: =IF(Q8>R8,"BJP","CONGRESS") -> BJP | AB8: 1005 | AD8: 467 | AF8: 538 | AH8: 888 | AJ8: 34 | AL8: 83 | AN8: =(AD8/AB8)*100 -> 46.467662 | AO8: =(AE8/AC8)*100 -> #DIV/0! | AP8: =(AF8/AB8)*100 -> 53.532338 | AQ8: =(AG8/AC8)*100 -> #DIV/0! | AR8: =IF(AN8>AP8,"MALE DOM","FEMALE DOM") -> FEMALE DOM | AS8: =IF(AO8>AP8,"MALE","FEMALE") -> #DIV/0! | AT8: =(AH8/AB8)*100 -> 88.358209 | AU8: =(AI8/AC8)*100 -> #DIV/0! | AV8: =(AJ8/AB8)*100 -> 3.3830846 | AW8: =(AK8/AC8)*100 -> #DIV/0! | AX8: =(AL8/AB8)*100 -> 8.2587065 | AY8: =(AM8/AC8)*100 -> #DIV/0! | AZ8: =IF(AT8>(AV8+AX8),"HINDU","MINORITY") -> HINDU | BA8: =IF(AU8>(AW8+AY8),"HIND","MINORITY") -> #DIV/0!
B9: 186 | C9: 823 | D9: 162 | E9: 450 | F9: 0 | G9: 4 | H9: 0 | I9: 0 | J9: 2 | K9: 3 | L9: 622 | M9: 0 | N9: 7 | O9: =D9+E9+F9+G9+H9+I9+J9+K9+N9 -> 628 | P9: =(O9/C9)*100 -> 76.306197 | Q9: =(E9/O9)*100 -> 71.656051 | R9: =(D9/O9)*100 -> 25.796178 | S9: =(F9/O9)*100 -> 0 | T9: =(G9/O9)*100 -> 0.63694268 | U9: =((H9+I9+J9+K9)/O9)*100 -> 0.79617834 | V9: =(N9/O9)*100 -> 1.1146497 | W9: =Q9-R9 -> 45.859873 | X9: =Q9-(R9+S9+T9+U9) -> 44.426752 | Y9: =IF(AND(W9<0,W9<=1),"LOST",IF(AND(W9>1,W9<=10),"NARROW",IF(AND(W9>10,W9<=40),"MEDIUM",IF(AND(W9>40,W9<=90),"STRONG","")))) -> STRONG | Z9: =IF(AND(P9<0,P9<=10),"WEAK",IF(AND(P9>10,P9<20),"BELOW AVG",IF(AND(P9>20,P9<=60),"MEDIUM",IF(AND(P9>60,P9<=90),"STRONG","")))) -> STRONG | AA9: =IF(Q9>R9,"BJP","CONGRESS") -> BJP | AB9: 818 | AD9: 401 | AF9: 417 | AH9: 632 | AJ9: 97 | AL9: 89 | AN9: =(AD9/AB9)*100 -> 49.022005 | AO9: =(AE9/AC9)*100 -> #DIV/0! | AP9: =(AF9/AB9)*100 -> 50.977995 | AQ9: =(AG9/AC9)*100 -> #DIV/0! | AR9: =IF(AN9>AP9,"MALE DOM","FEMALE DOM") -> FEMALE DOM | AS9: =IF(AO9>AP9,"MALE","FEMALE") -> #DIV/0! | AT9: =(AH9/AB9)*100 -> 77.261614 | AU9: =(AI9/AC9)*100 -> #DIV/0! | AV9: =(AJ9/AB9)*100 -> 11.858191 | AW9: =(AK9/AC9)*100 -> #DIV/0! | AX9: =(AL9/AB9)*100 -> 10.880196 | AY9: =(AM9/AC9)*100 -> #DIV/0! | AZ9: =IF(AT9>(AV9+AX9),"HINDU","MINORITY") -> HINDU | BA9: =IF(AU9>(AW9+AY9),"HIND","MINORITY") -> #DIV/0!
B10: 185 | C10: 523 | D10: 148 | E10: 174 | F10: 1 | G10: 1 | H10: 0 | I10: 0 | J10: 0 | K10: 0 | L10: 324 | M10: 0 | N10: 5 | O10: =D10+E10+F10+G10+H10+I10+J10+K10+N10 -> 329 | P10: =(O10/C10)*100 -> 62.90631 | Q10: =(E10/O10)*100 -> 52.887538 | R10: =(D10/O10)*100 -> 44.984802 | S10: =(F10/O10)*100 -> 0.30395137 | T10: =(G10/O10)*100 -> 0.30395137 | U10: =((H10+I10+J10+K10)/O10)*100 -> 0 | V10: =(N10/O10)*100 -> 1.5197568 | W10: =Q10-R10 -> 7.9027356 | X10: =Q10-(R10+S10+T10+U10) -> 7.2948328 | Y10: =IF(AND(W10<0,W10<=1),"LOST",IF(AND(W10>1,W10<=10),"NARROW",IF(AND(W10>10,W10<=40),"MEDIUM",IF(AND(W10>40,W10<=90),"STRONG","")))) -> NARROW | Z10: =IF(AND(P10<0,P10<=10),"WEAK",IF(AND(P10>10,P10<20),"BELOW AVG",IF(AND(P10>20,P10<=60),"MEDIUM",IF(AND(P10>60,P10<=90),"STRONG","")))) -> STRONG | AA10: =IF(Q10>R10,"BJP","CONGRESS") -> BJP | AB10: 519 | AD10: 248 | AF10: 271 | AH10: 283 | AJ10: 231 | AL10: 5 | AN10: =(AD10/AB10)*100 -> 47.7842 | AO10: =(AE10/AC10)*100 -> #DIV/0! | AP10: =(AF10/AB10)*100 -> 52.2158 | AQ10: =(AG10/AC10)*100 -> #DIV/0! | AR10: =IF(AN10>AP10,"MALE DOM","FEMALE DOM") -> FEMALE DOM | AS10: =IF(AO10>AP10,"MALE","FEMALE") -> #DIV/0! | AT10: =(AH10/AB10)*100 -> 54.527938 | AU10: =(AI10/AC10)*100 -> #DIV/0! | AV10: =(AJ10/AB10)*100 -> 44.508671 | AW10: =(AK10/AC10)*100 -> #DIV/0! | AX10: =(AL10/AB10)*100 -> 0.96339114 | AY10: =(AM10/AC10)*100 -> #DIV/0! | AZ10: =IF(AT10>(AV10+AX10),"HINDU","MINORITY") -> HINDU | BA10: =IF(AU10>(AW10+AY10),"HIND","MINORITY") -> #DIV/0!
B11: 184 | C11: 841 | D11: 128 | E11: 402 | F11: 2 | G11: 7 | H11: 1 | I11: 0 | J11: 0 | K11: 3 | L11: 543 | M11: 0 | N11: 2 | O11: =D11+E11+F11+G11+H11+I11+J11+K11+N11 -> 545 | P11: =(O11/C11)*100 -> 64.803805 | Q11: =(E11/O11)*100 -> 73.761468 | R11: =(D11/O11)*100 -> 23.486239 | S11: =(F11/O11)*100 -> 0.36697248 | T11: =(G11/O11)*100 -> 1.2844037 | U11: =((H11+I11+J11+K11)/O11)*100 -> 0.73394495 | V11: =(N11/O11)*100 -> 0.36697248 | W11: =Q11-R11 -> 50.275229 | X11: =Q11-(R11+S11+T11+U11) -> 47.889908 | Y11: =IF(AND(W11<0,W11<=1),"LOST",IF(AND(W11>1,W11<=10),"NARROW",IF(AND(W11>10,W11<=40),"MEDIUM",IF(AND(W11>40,W11<=90),"STRONG","")))) -> STRONG | Z11: =IF(AND(P11<0,P11<=10),"WEAK",IF(AND(P11>10,P11<20),"BELOW AVG",IF(AND(P11>20,P11<=60),"MEDIUM",IF(AND(P11>60,P11<=90),"STRONG","")))) -> STRONG | AA11: =IF(Q11>R11,"BJP","CONGRESS") -> BJP | AB11: 838 | AC11: 543 | AD11: 404 | AE11: 257 | AF11: 434 | AG11: 286 | AH11: 703 | AI11: 470 | AJ11: 20 | AK11: 18 | AL11: 115 | AM11: 55 | AN11: =(AD11/AB11)*100 -> 48.210024 | AO11: =(AE11/AC11)*100 -> 47.32965 | AP11: =(AF11/AB11)*100 -> 51.789976 | AQ11: =(AG11/AC11)*100 -> 52.67035 | AR11: =IF(AN11>AP11,"MALE DOM","FEMALE DOM") -> FEMALE DOM | AS11: =IF(AO11>AP11,"MALE","FEMALE") -> FEMALE | AT11: =(AH11/AB11)*100 -> 83.890215 | AU11: =(AI11/AC11)*100 -> 86.556169 | AV11: =(AJ11/AB11)*100 -> 2.3866348 | AW11: =(AK11/AC11)*100 -> 3.3149171 | AX11: =(AL11/AB11)*100 -> 13.72315 | AY11: =(AM11/AC11)*100 -> 10.128913 | AZ11: =IF(AT11>(AV11+AX11),"HINDU","MINORITY") -> HINDU | BA11: =IF(AU11>(AW11+AY11),"HIND","MINORITY") -> HIND
B12: 209 | C12: 777 | D12: 218 | E12: 361 | F12: 1 | G12: 4 | H12: 0 | I12: 0 | J12: 0 | K12: 0 | L12: 584 | M12: 0 | N12: 2 | O12: =D12+E12+F12+G12+H12+I12+J12+K12+N12 -> 586 | P12: =(O12/C12)*100 -> 75.418275 | Q12: =(E12/O12)*100 -> 61.604096 | R12: =(D12/O12)*100 -> 37.201365 | S12: =(F12/O12)*100 -> 0.17064846 | T12: =(G12/O12)*100 -> 0.68259386 | U12: =((H12+I12+J12+K12)/O12)*100 -> 0 | V12: =(N12/O12)*100 -> 0.34129693 | W12: =Q12-R12 -> 24.40273 | X12: =Q12-(R12+S12+T12+U12) -> 23.549488 | Y12: =IF(AND(W12<0,W12<=1),"LOST",IF(AND(W12>1,W12<=10),"NARROW",IF(AND(W12>10,W12<=40),"MEDIUM",IF(AND(W12>40,W12<=90),"STRONG","")))) -> MEDIUM | Z12: =IF(AND(P12<0,P12<=10),"WEAK",IF(AND(P12>10,P12<20),"BELOW AVG",IF(AND(P12>20,P12<=60),"MEDIUM",IF(AND(P12>60,P12<=90),"STRONG","")))) -> STRONG | AA12: =IF(Q12>R12,"BJP","CONGRESS") -> BJP | AB12: 771 | AC12: 579 | AD12: 370 | AE12: 272 | AF12: 401 | AG12: 307 | AH12: 560 | AI12: 450 | AJ12: 12 | AK12: 6 | AL12: 199 | AM12: 123 | AN12: =(AD12/AB12)*100 -> 47.989624 | AO12: =(AE12/AC12)*100 -> 46.977547 | AP12: =(AF12/AB12)*100 -> 52.010376 | AQ12: =(AG12/AC12)*100 -> 53.022453 | AR12: =IF(AN12>AP12,"MALE DOM","FEMALE DOM") -> FEMALE DOM | AS12: =IF(AO12>AP12,"MALE","FEMALE") -> FEMALE | AT12: =(AH12/AB12)*100 -> 72.632944 | AU12: =(AI12/AC12)*100 -> 77.720207 | AV12: =(AJ12/AB12)*100 -> 1.5564202 | AW12: =(AK12/AC12)*100 -> 1.0362694 | AX12: =(AL12/AB12)*100 -> 25.810636 | AY12: =(AM12/AC12)*100 -> 21.243523 | AZ12: =IF(AT12>(AV12+AX12),"HINDU","MINORITY") -> HINDU | BA12: =IF(AU12>(AW12+AY12),"HIND","MINORITY") -> HIND
B13: 210 | C13: 663 | D13: 153 | E13: 300 | F13: 5 | G13: 2 | H13: 0 | I13: 0 | J13: 0 | K13: 1 | L13: 461 | M13: 0 | N13: 1 | O13: =D13+E13+F13+G13+H13+I13+J13+K13+N13 -> 462 | P13: =(O13/C13)*100 -> 69.683258 | Q13: =(E13/O13)*100 -> 64.935065 | R13: =(D13/O13)*100 -> 33.116883 | S13: =(F13/O13)*100 -> 1.0822511 | T13: =(G13/O13)*100 -> 0.43290043 | U13: =((H13+I13+J13+K13)/O13)*100 -> 0.21645022 | V13: =(N13/O13)*100 -> 0.21645022 | W13: =Q13-R13 -> 31.818182 | X13: =Q13-(R13+S13+T13+U13) -> 30.08658 | Y13: =IF(AND(W13<0,W13<=1),"LOST",IF(AND(W13>1,W13<=10),"NARROW",IF(AND(W13>10,W13<=40),"MEDIUM",IF(AND(W13>40,W13<=90),"STRONG","")))) -> MEDIUM | Z13: =IF(AND(P13<0,P13<=10),"WEAK",IF(AND(P13>10,P13<20),"BELOW AVG",IF(AND(P13>20,P13<=60),"MEDIUM",IF(AND(P13>60,P13<=90),"STRONG","")))) -> STRONG | AA13: =IF(Q13>R13,"BJP","CONGRESS") -> BJP | AB13: 663 | AD13: 309 | AF13: 354 | AH13: 482 | AJ13: 50 | AL13: 131 | AN13: =(AD13/AB13)*100 -> 46.606335 | AO13: =(AE13/AC13)*100 -> #DIV/0! | AP13: =(AF13/AB13)*100 -> 53.393665 | AQ13: =(AF13/AC13)*100 -> #DIV/0! | AR13: =IF(AN13>AP13,"MALE DOM","FEMALE DOM") -> FEMALE DOM | AS13: =IF(AO13>AP13,"MALE","FEMALE") -> #DIV/0! | AT13: =(AH13/AB13)*100 -> 72.699849 | AU13: =(AI13/AC13)*100 -> #DIV/0! | AV13: =(AJ13/AB13)*100 -> 7.5414781 | AW13: =(AK13/AC13)*100 -> #DIV/0! | AX13: =(AL13/AB13)*100 -> 19.758673 | AY13: =(AM13/AC13)*100 -> #DIV/0! | AZ13: =IF(AT13>(AV13+AX13),"HINDU","MINORITY") -> HINDU | BA13: =IF(AU13>(AW13+AY13),"HIND","MINORITY") -> #DIV/0!
C14: =SUM(C7:C13) -> 5712 | D14: =SUM(D7:D13) -> 1194 | E14: =SUM(E7:E13) -> 2746 | F14: =SUM(F7:F13) -> 14 | G14: =SUM(G7:G13) -> 25 | H14: =SUM(H7:H13) -> 1 | I14: =SUM(I7:I13) -> 0 | J14: =SUM(J7:J13) -> 2 | ... O14: =SUM(O7:O13) -> 4016 | P14: =AVERAGE(P7:P13) -> 69.985075 | Q14: =AVERAGE(Q7:Q13) -> 67.045568 | R14: =AVERAGE(R7:R13) -> 31.01562 | S14: =AVERAGE(S7:S13) -> 0.3722788 | T14: =AVERAGE(T7:T13) -> 0.61368165 | U14: =AVERAGE(U7:U13) -> 0.28848926 | V14: =AVERAGE(V7:V13) -> 0.66436162 | W14: =AVERAGE(W7:W13) -> 36.029948 | X14: =AVERAGE(X7:X13) -> 34.755498 | Y14: =IF(AND(W14<0,W14<=1),"LOST",IF(AND(W14>1,W14<=10),"NARROW",IF(AND(W14>10,W14<=40),"MEDIUM",IF(AND(W14>40,W14<=90),"STRONG","")))) -> MEDIUM | Z14: =IF(AND(P14<0,P14<=10),"WEAK",IF(AND(P14>10,P14<20),"BELOW AVG",IF(AND(P14>20,P14<=60),"MEDIUM",IF(AND(P14>60,P14<=90),"STRONG","")))) -> STRONG | AA14: =IF(Q14>R14,"BJP","CONGRESS") -> BJP | AB14: =SUM(AB7:AB13) -> 5682 | AC14: =SUM(AC13) -> 0 | AD14: =SUM(AD7:AD13) -> 2710 | AE14: =SUM(AE13) -> 0 | AF14: =SUM(AF7:AF13) -> 2971 | AG14: =SUM(AG7) -> 381
C22: TOTAL BOOTH 7 | H22: BOOTH WISE CATEGORIZATION | M22: COMPARITIVE ANALYSIS
C24: BJP WON | F24: =COUNTIF(AA7:AA13,"BJP") -> 7 | H24: NARROW | K24: =COUNTIF(Y7:Y13,"NARROW") -> 1 | M24: BJP %(2018) | P24: ='ALAPE-S18'!E10 -> 61.811415 | Q24: BJP%(2023) | T24: =Q14 -> 67.045568
H26: MEDIUM | K26: =COUNTIF(Y7:Y13,"MEDIUM") -> 3 | M26: CONGRESS %(2018) | P26: ='ALAPE-S18'!G10 -> 32.719776 | Q26: CONGRESS%(2023) | T26: =R14 -> 31.01562
